Workbook

Sheet averaged_runs126
A1: method_name | B1: method_class | C1: c/r | D1: #q<0.1 | E1: #q<0.5 | F1: 100bias | G1: 100log-l | H1: Edyrs15 | I1: Edyrs20 | J1: EdyrsA | K1: Fdyrs15 | L1: Fdyrs20 | M1: Mdyrs15 | N1: Mdyrs20 | O1: RMSyrsA | P1: avg_unc.(1se) | Q1: bias | R1: bias50 | S1: e100bias | T1: e100log-l | U1: eEdyrs15 | V1: eEdyrs20 | W1: eEdyrsA | X1: eFdyrs15 | Y1: eFdyrs20 | Z1: eMdyrs15 | AA1: eMdyrs20 | AB1: eRMSyrsA | AC1: ebias50 | AD1: el15 | AE1: el20 | AF1: l15 | AG1: l20 | AH1: log-likeli | AI1: ncEdyrs | AJ1: nceEdyrs | AK1: q_min | AL1: q_small5 | AM1: smooth_r | AN1: tlog-l | AO1: RMS | AP1: 100RMS | AQ1: 75RMS | AR1: e100RMS | AS1: e75RMS
A2: lag10y | B2: 42/1_Run_Means | C2: c | D2: 25.98 | E2: 97.58 | F2: -0.03512145 | G2: 69.573514 | H2: 5.58 | I2: -1 | J2: 4.652166 | K2: 4.0533333 | L2: -1 | M2: 7.1233333 | N2: -1 | O2: 5.1556895 | P2: 0.038675018 | Q2: -0.029860933 | R2: 0.0056395683 | S2: -0.03512145 | T2: -29.955838 | U2: 5.7808333 | V2: -1 | W2: 4.8508796 | X2: 4.345 | Y2: -1 | Z2: 6.5983333 | AA2: -1 | AB2: 4.925787 | AC2: 0.0056395683 | AD2: 5.2325459 | AE2: 0 | AF2: 4.7792099 | AG2: 0 | AH2: 1.0311162 | AI2: 7.42 | AJ2: 7.572 | AK2: 0.008651632 | AL2: 0.017768616 | AM2: 2.89858 | AN2: 238.18784 | AO2: 0.058968735 | AP2: 0.061551365 | AQ2: 0.047594499 | AR2: 0.078150232 | AS2: 0.067391861
A3: lag5y | B3: 42/1_Run_Means | C3: c | D3: 24.32 | E3: 75.24 | F3: -0.0098237311 | G3: 63.33851 | H3: 3.5749722 | I3: -1 | J3: 2.5327632 | K3: -1.015 | L3: -1 | M3: 6.2366667 | N3: -1 | O3: 3.7035893 | P3: 0.047763977 | Q3: -0.013327305 | R3: 0.0057650713 | S3: -0.0098237311 | T3: -30.543426 | U3: 3.78525 | V3: -1 | W3: 2.8088611 | X3: -0.705 | Y3: -1 | Z3: 6.0783333 | AA3: -1 | AB3: 3.4273333 | AC3: 0.0057650713 | AD3: 4.9406481 | AE3: 0 | AF3: 6.1213312 | AG3: 0 | AH3: 0.80247022 | AI3: 10.566 | AJ3: 10.956 | AK3: 0.00064298482 | AL3: 0.0051331553 | AM3: 5.66122 | AN3: 185.37062 | AO3: 0.065011772 | AP3: 0.05783862 | AQ3: 0.054920579 | AR3: 0.075144506 | AS3: 0.072903523
A4: offset11y | B4: 42/1_Run_Means | C4: c | D4: 127.04 | E4: 189.14 | F4: 0.069619453 | G4: -140.04655 | H4: -4.26 | I4: -1 | J4: -3.1889775 | K4: -4.335 | L4: -1 | M4: -4.335 | N4: -1 | O4: 4.8726123 | P4: 0.037443796 | Q4: 0.076804215 | R4: 0.11512772 | S4: 0.069619453 | T4: -215.39941 | U4: -3.7716667 | V4: -1 | W4: -3.5803704 | X4: -3.8466667 | Y4: -1 | Z4: -3.7766667 | AA4: -1 | AB4: 4.1475926 | AC4: 0.11512772 | AD4: 4.2871552 | AE4: 0 | AF4: 4.9908594 | AG4: 0 | AH4: -1.4505 | AI4: 6.488 | AJ4: 6.688 | AK4: 1.3697832e-06 | AL4: 5.8065895e-06 | AM4: 2.6265 | AN4: -335.0655 | AO4: 0.093010316 | AP4: 0.087836824 | AQ4: 0.10040616 | AR4: 0.099664703 | AS4: 0.11069738
A5: raw1y | B5: 42/1_Run_Means | C5: c | D5: 0.04 | E5: 0.68 | F5: 0.0067338295 | G5: 65.576952 | H5: 3.2360218 | I5: -1 | J5: 1.0028065 | K5: -9.7766667 | L5: -1 | M5: 12.096667 | N5: -1 | O5: 3.3224325 | P5: 0.12803787 | Q5: -0.0002616694 | R5: 0.0027164812 | S5: 0.0067338295 | T5: 58.287686 | U5: 3.644707 | V5: -1 | W5: 0.94941766 | X5: -9.2883333 | Y5: -1 | Z5: 14.095 | AA5: -1 | AB5: 2.4880063 | AC5: 0.0027164812 | AD5: 2.3654558 | AE5: 0 | AF5: 2.3150115 | AG5: 0 | AH5: 0.69741762 | AI5: 28.292 | AJ5: 29.548 | AK5: 0.64924814 | AL5: 0.86565755 | AM5: 28.95268 | AN5: 161.10347 | AO5: 0.11944902 | AP5: 0.11805462 | AQ5: 0.11668998 | AR5: 0.1274252 | AS5: 0.12648575
A6: Bayes_seq_CP | B6: 42/2_LT_Fits | C6: c | D6: 74.02 | E6: 122.82 | F6: 0.035388579 | G6: -44.928597 | H6: -1.9977778 | I6: -1 | J6: -1.2727798 | K6: -2.9983333 | L6: -1 | M6: -1.6616667 | N6: -1 | O6: 4.147544 | P6: 0.033354272 | Q6: -0.0038902264 | R6: 0.078471048 | S6: 0.035388579 | T6: -148.3518 | U6: -1.7619444 | V6: -1 | W6: -1.2444907 | X6: -2.51 | Y6: -1 | Z6: -1.205 | AA6: -1 | AB6: 3.2975463 | AC6: 0.078471048 | AD6: 4.4206577 | AE6: 0 | AF6: 5.6462451 | AG6: 0 | AH6: -1.0426181 | AI6: 6.442 | AJ6: 6.758 | AK6: 8.6998641e-06 | AL6: 1.9019264e-05 | AM6: 2.52098 | AN6: -200.18267 | AO6: 0.076147336 | AP6: 0.075184409 | AQ6: 0.080408488 | AR6: 0.089864415 | AS6: 0.093375968
A7: butterworth | B7: 42/2_LT_Fits | C7: c | D7: 0.88 | E7: 1.56 | F7: -0.011733433 | G7: 94.635582 | H7: 2.3254167 | I7: -1 | J7: 1.6773209 | K7: -2.81 | L7: -1 | M7: 5.5366667 | N7: -1 | O7: 3.0756617 | P7: 0.13135765 | Q7: -0.018319597 | R7: -0.0027805941 | S7: -0.011733433 | T7: 74.974012 | U7: 2.2081389 | V7: -1 | W7: 1.7153194 | X7: -2.3216667 | Y7: -1 | Z7: 4.4266667 | AA7: -1 | AB7: 2.9370509 | AC7: -0.0027805941 | AD7: 2.8812973 | AE7: 0 | AF7: 3.1077999 | AG7: 0 | AH7: 0.97177602 | AI7: 12.608 | AJ7: 13.058 | AK7: 0.37033581 | AL7: 0.92358654 | AM7: 8.82322 | AN7: 137.99219 | AO7: 0.062060846 | AP7: 0.05537896 | AQ7: 0.051943554 | AR7: 0.075027736 | AS7: 0.073231793
A8: hinge75meet | B8: 42/2_LT_Fits | C8: c | D8: 50.34 | E8: 74.96 | F8: 0.15264623 | G8: -373.74809 | H8: -5.345 | I8: -1 | J8: -3.6060397 | K8: -5.345 | L8: -1 | M8: -5.345 | N8: -1 | O8: 6.084276 | P8: 0.066111897 | Q8: 0.090328395 | R8: 0.30027986 | S8: 0.15264623 | T8: -391.07162 | U8: -4.8566667 | V8: -1 | W8: -4.3016667 | X8: -4.8566667 | Y8: -1 | Z8: -4.8566667 | AA8: -1 | AB8: 4.5122222 | AC8: 0.30027986 | AD8: 2.9901692 | AE8: 0 | AF8: 3.002033 | AG8: 0 | AH8: -1.9111686 | AI8: 5.82 | AJ8: 6 | AK8: 3.8112199e-08 | AL8: 8.9933926e-08 | AM8: 1.69648 | AN8: -298.1423 | AO8: 0.170386 | AP8: 0.21725339 | AQ8: 0.25372763 | AR8: 0.2203762 | AS8: 0.255589
A9: OLS_hinge75 | B9: 42/2_LT_Fits | C9: c | D9: 59.94 | E9: 99.7 | F9: 0.11105045 | G9: -987.96727 | H9: -4.0066667 | I9: -1 | J9: -2.6526508 | K9: -4.0066667 | L9: -1 | M9: -4.0066667 | N9: -1 | O9: 5.1027109 | P9: 0.038055601 | Q9: 0.060938062 | R9: 0.22978882 | S9: 0.11105045 | T9: -1052.0831 | U9: -3.5183333 | V9: -1 | W9: -3.1491667 | X9: -3.5183333 | Y9: -1 | Z9: -3.5183333 | AA9: -1 | AB9: 3.7436111 | AC9: 0.22978882 | AD9: 3.5341999 | AE9: 0 | AF9: 3.8493514 | AG9: 0 | AH9: -6.1874545 | AI9: 5.84 | AJ9: 6 | AK9: 5.6596065e-17 | AL9: 8.5939632e-16 | AM9: 2.05546 | AN9: -965.2429 | AO9: 0.13428301 | AP9: 0.16727605 | AQ9: 0.19441842 | AR9: 0.17135848 | AS9: 0.1969897
A10: OLS_refit | B10: 42/2_LT_Fits | C10: c | D10: 108.74 | E10: 126.72 | F10: -0.092704768 | G10: -1638.0177 | H10: 12.763333 | I10: -1 | J10: 12.887302 | K10: 12.763333 | L10: -1 | M10: 12.763333 | N10: -1 | O10: 13.398005 | P10: 0.029751833 | Q10: -0.06847154 | R10: 0.068994971 | S10: -0.092704768 | T10: -1708.964 | U10: 13.251667 | V10: -1 | W10: 12.654167 | X10: 13.251667 | Y10: -1 | Z10: 13.251667 | AA10: -1 | AB10: 12.654167 | AC10: 0.068994971 | AD10: 0.0011958259 | AE10: 0 | AF10: 0.1200225 | AG10: 0 | AH10: -12.563828 | AI10: 5.86 | AJ10: 6 | AK10: 3.35039e-16 | AL10: 1.2029271e-14 | AM10: 0.76104 | AN10: -1771.4997 | AO10: 0.16503284 | AP10: 0.19372691 | AQ10: 0.17402959 | AR10: 0.19516525 | AS10: 0.17518041
A11: quartic | B11: 42/2_LT_Fits | C11: c | D11: 33.36 | E11: 90.02 | F11: 0.07574405 | G11: 4.7964935 | H11: -9.1680556 | I11: -1 | J11: -7.0786376 | K11: -9.4266667 | L11: -1 | M11: -9.4266667 | N11: -1 | O11: 8.6546492 | P11: 0.051222183 | Q11: 0.033631702 | R11: 0.056870041 | S11: 0.07574405 | T11: -46.020053 | U11: -8.6797222 | V11: -1 | W11: -7.222037 | X11: -8.9383333 | Y11: -1 | Z11: -8.9383333 | AA11: -1 | AB11: 7.5564815 | AC11: 0.056870041 | AD11: 1.6857878 | AE11: 0 | AF11: 1.7768126 | AG11: 0 | AH11: 0.36834862 | AI11: 6.346 | AJ11: 6.646 | AK11: 0.01216596 | AL11: 0.031040829 | AM11: 3.0357 | AN11: 51.937155 | AO11: 0.092381197 | AP11: 0.0985686 | AQ11: 0.10371068 | AR11: 0.11148384 | AS11: 0.11492696
A12: TheilSen_h7075 | B12: 42/2_LT_Fits | C12: c | D12: 71.62 | E12: 107.2 | F12: 0.14301039 | G12: -2100.8047 | H12: -4.6516667 | I12: -1 | J12: -2.0578294 | K12: -4.6516667 | L12: -1 | M12: -4.6516667 | N12: -1 | O12: 6.1921992 | P12: 0.03891404 | Q12: 0.07748072 | R12: 0.31958925 | S12: 0.14301039 | T12: -2166.3442 | U12: -4.1633333 | V12: -1 | W12: -2.9420833 | X12: -4.1633333 | Y12: -1 | Z12: -4.1633333 | AA12: -1 | AB12: 3.6865278 | AC12: 0.31958925 | AD12: 3.4473758 | AE12: 0 | AF12: 2.5865605 | AG12: 0 | AH12: -12.918255 | AI12: 5.82 | AJ12: 6.02 | AK12: 5.9611312e-33 | AL12: 6.4012116e-26 | AM12: 2.03348 | AN12: -2015.2477 | AO12: 0.18622938 | AP12: 0.23835769 | AQ12: 0.27552542 | AR12: 0.24069926 | AS12: 0.27685374
A13: etrend15y | B13: 42/3_ST_Fits | C13: c | D13: 5.46 | E13: 31.34 | F13: 0.011758058 | G13: 125.0034 | H13: 1.4840278 | I13: -1 | J13: 0.072364418 | K13: -3.6916667 | L13: -1 | M13: 4.175 | N13: -1 | O13: 3.1278171 | P13: 0.058801633 | Q13: 0.00031823379 | R13: 0.0096860304 | S13: 0.011758058 | T13: 81.889742 | U13: 1.4026389 | V13: -1 | W13: 0.30143056 | X13: -3.2033333 | Y13: -1 | Z13: 3.07 | AA13: -1 | AB13: 2.8999583 | AC13: 0.0096860304 | AD13: 4.2337379 | AE13: 0 | AF13: 5.3278847 | AG13: 0 | AH13: 1.1671168 | AI13: 10.57 | AJ13: 10.94 | AK13: 0.1339021 | AL13: 0.21580287 | AM13: 5.69426 | AN13: 264.93551 | AO13: 0.067006276 | AP13: 0.058229286 | AQ13: 0.054974865 | AR13: 0.079512276 | AS13: 0.077378821
... A61: CGWL10y_sUKCP | B61: 44/44_EarthModel_CGWL | C61: c | D61: 0 | E61: 0.02 | F61: 0.028244594 | G61: 142.66175 | H61: -0.60361111 | I61: -1 | J61: -1.1596885 | K61: -1.89 | L61: -1 | M61: -0.96833333 | N61: -1 | O61: 3.2282412 | P61: 0.053808094 | Q61: 0.0093545861 | R61: 0.032636563 | S61: 0.028244594 | T61: 113.55473 | U61: -0.24277778 | V61: -1 | W61: -1.0650926 | X61: -1.4016667 | Y61: -1 | Z61: 0.32666667 | AA61: -1 | AB61: 3.3906481 | AC61: 0.032636563 | AD61: 3.9822022 | AE61: 0 | AF61: 5.2916982 | AG61: 0 | AH61: 1.6125365 | AI61: 7.938 | AJ61: 8.196 | AK61: 0.96189151 | AL61: 0.97199565 | AM61: 3.18452 | AN61: 354.75803 | AO61: 0.044272719 | AP61: 0.044007046 | AQ61: 0.043414286 | AR61: 0.0659115 | AS61: 0.065336415

Sheet averaged_runs245
A1: method_name | B1: method_class | C1: 0.06 | J1: c/r | K1: #q<0.1 | L1: #q<0.5 | M1: 100bias | N1: 100log-l | O1: Edyrs15 | P1: Edyrs20 | Q1: EdyrsA | R1: Fdyrs15 | S1: Fdyrs20 | T1: Mdyrs15 | U1: Mdyrs20 | V1: RMSyrsA | W1: avg_unc.(1se) | X1: bias | Y1: bias50 | Z1: e100bias | AA1: e100log-l | AB1: eEdyrs15 | AC1: eEdyrs20 | AD1: eEdyrsA | AE1: eFdyrs15 | AF1: eFdyrs20 | AG1: eMdyrs15 | AH1: eMdyrs20 | AI1: eRMSyrsA | AJ1: ebias50 | AK1: el15 | AL1: el20 | AM1: l15 | AN1: l20 | AO1: log-likeli | AP1: ncEdyrs | AQ1: nceEdyrs | AR1: q_min | AS1: q_small5 | AT1: smooth_r | AU1: tlog-l | AV1: RMS | AW1: 100RMS | AX1: 75RMS | AY1: e100RMS | AZ1: e75RMS
A2: lag10y | B2: 42/1_Run_Means | C2: =IF(ISNUMBER(D2),SUM(INDIRECT(_xlfn.CONCAT("e",ROW(),":e",ROW()+D2-1))),"") | D2: 4 | E2: =AND(AX2<$C$1,averaged_runs370!AQ2<$C$1,averaged_runs126!AQ2<$C$1)*1 | F2: =IF(TRUE,SQRT(averaged_runs126!AQ2^2/2+averaged_runs370!AQ2^2/2+AX2^2*0),"") | J2: c | K2: 56.36 | L2: 146.24 | M2: -0.079159696 | N2: -73.534175 | O2: 4.75 | P2: 4.0125 | Q2: 4.4067918 | R2: 4.75 | S2: 3.9216667 | T2: 4.75 | U2: 4.1033333 | V2: 4.6506002 | W2: 0.039112734 | X2: -0.047209333 | Y2: -0.065017192 | Z2: -0.079159696 | AA2: -147.21372 | AB2: 4.7516667 | AC2: 4.0158333 | AD2: 4.5007937 | AE2: 4.7516667 | AF2: 3.925 | AG2: 4.7516667 | AH2: 4.1066667 | AI2: 4.5007937 | AJ2: -0.065017192 | AK2: 1.7247835 | AL2: 3.0566785 | AM2: 0.93529634 | AN2: 1.8610675 | AO2: 0.41160237 | AP2: 14.58 | AQ2: 14.9 | AR2: 0.00031624885 | AS2: 0.0017976906 | AT2: 2.90498 | AU2: 95.080147 | AV2: 0.070229371 | AW2: 0.086496581 | AX2: 0.084744435 | AY2: 0.096465288 | AZ2: 0.094198136
A3: lag5y | B3: 42/1_Run_Means | C3: =IF(ISNUMBER(D3),SUM(INDIRECT(_xlfn.CONCAT("e",ROW(),":e",ROW()+D3-1))),"") | E3: =AND(AX3<$C$1,averaged_runs370!AQ3<$C$1,averaged_runs126!AQ3<$C$1)*1 | F3: =IF(TRUE,SQRT(averaged_runs126!AQ3^2/2+averaged_runs370!AQ3^2/2+AX3^2*0),"") | G3: =IF(TRUE,averaged_runs126!AQ3,"") | H3: =IF(TRUE,AX3,"") | I3: =IF(TRUE,averaged_runs370!AQ3,"") | J3: c | K3: 26.36 | L3: 80.12 | M3: -0.031352729 | N3: 47.236116 | O3: 2.3425 | P3: 1.9233333 | Q3: 2.0182975 | R3: 1.8783333 | S3: 0.895 | T3: 2.725 | U3: 2.985 | V3: 2.6934022 | W3: 0.047655883 | X3: -0.021808425 | Y3: -0.025380273 | Z3: -0.031352729 | AA3: -22.616547 | AB3: 2.3441667 | AC3: 1.9266667 | AD3: 2.0310516 | AE3: 1.88 | AF3: 0.89833333 | AG3: 2.8083333 | AH3: 2.7033333 | AI3: 2.2024008 | AJ3: -0.025380273 | AK3: 4.38429 | AL3: 4.0992214 | AM3: 4.1252922 | AN3: 5.7113948 | AO3: 0.73276289 | AP3: 18.248 | AQ3: 18.848 | AR3: 1.8491634e-05 | AS3: 0.0026641236 | AT3: 5.648 | AU3: 169.26823 | AV3: 0.066737622 | AW3: 0.062629872 | AX3: 0.061261305 | AY3: 0.075140154 | AZ3: 0.07364617
A4: offset11y | B4: 42/1_Run_Means | E4: =AND(AX4<$C$1,averaged_runs370!AQ4<$C$1,averaged_runs126!AQ4<$C$1)*1 | F4: =IF(TRUE,SQRT(averaged_runs126!AQ4^2/2+averaged_runs370!AQ4^2/2+AX4^2*0),"") | J4: c | K4: 81.96 | L4: 150.28 | M4: 0.021231508 | N4: 150.98407 | O4: -0.20833333 | P4: -0.845 | Q4: -1.2218162 | R4: -0.275 | S4: -0.92666667 | T4: -0.21166667 | U4: -0.92666667 | V4: 2.4454214 | W4: 0.038004066 | X4: 0.057742298 | Y4: 0.036629054 | Z4: 0.021231508 | AA4: 87.83996 | AB4: -0.20666667 | AC4: -0.84166667 | AD4: -1.3748016 | AE4: -0.27333333 | AF4: -0.92333333 | AG4: -0.21 | AH4: -0.92333333 | AI4: 1.7928968 | AJ4: 0.036629054 | AK4: 6.5489616 | AL4: 5.9250551 | AM4: 8.6823255 | AN4: 8.041327 | AO4: -0.19062716 | AP4: 14.288 | AQ4: 14.788 | AR4: 1.2653184e-05 | AS4: 6.1371312e-05 | AT4: 2.65052 | AU4: -44.034875 | AV4: 0.079072113 | AW4: 0.040333084 | AX4: 0.041896101 | AY4: 0.058086558 | AZ4: 0.058004208
A5: raw1y | B5: 42/1_Run_Means | C5: =IF(ISNUMBER(D5),SUM(INDIRECT(_xlfn.CONCAT("e",ROW(),":e",ROW()+D5-1))),"") | E5: =AND(AX5<$C$1,averaged_runs370!AQ5<$C$1,averaged_runs126!AQ5<$C$1)*1 | F5: =IF(TRUE,SQRT(averaged_runs126!AQ5^2/2+averaged_runs370!AQ5^2/2+AX5^2*0),"") | J5: c | K5: 0.04 | L5: 0.9 | M5: 0.0044324491 | N5: 67.196781 | O5: -0.13513889 | P5: 1.1801944 | Q5: -0.1290435 | R5: -4.97 | S5: -5.335 | T5: -1.1283333 | U5: 4.9716667 | V5: 2.5170091 | W5: 0.12719177 | X5: -0.0011682738 | Y5: 0.0046354121 | Z5: 0.0044324491 | AA5: 61.751561 | AB5: -0.13347222 | AC5: 1.1835278 | AD5: -0.27151077 | AE5: -4.9683333 | AF5: -5.3316667 | AG5: -0.35333333 | AH5: 5.2533333 | AI5: 1.4112829 | AJ5: 0.0046354121 | AK5: 2.3368714 | AL5: 2.3018707 | AM5: 2.5264418 | AN5: 2.2629885 | AO5: 0.7048187 | AP5: 47.708 | AQ5: 49.568 | AR5: 0.62227742 | AS5: 0.8793021 | AT5: 29.13192 | AU5: 162.81312 | AV5: 0.11853365 | AW5: 0.11568884 | AX5: 0.11360491 | AY5: 0.1228443 | AZ5: 0.12087569
A6: Bayes_seq_CP | B6: 42/2_LT_Fits | C6: =IF(ISNUMBER(D6),SUM(INDIRECT(_xlfn.CONCAT("e",ROW(),":e",ROW()+D6-1))),"") | D6: 7 | E6: =AND(AX6<$C$1,averaged_runs370!AQ6<$C$1,averaged_runs126!AQ6<$C$1)*1 | F6: =IF(TRUE,SQRT(averaged_runs126!AQ6^2/2+averaged_runs370!AQ6^2/2+AX6^2*0),"") | J6: c | K6: 65.24 | L6: 119.46 | M6: -0.0047616235 | N6: 40.959228 | O6: 1.395 | P6: 0.68666667 | Q6: 0.17849054 | R6: 1.395 | S6: 0.68666667 | T6: 1.395 | U6: 0.68666667 | V6: 2.6191002 | W6: 0.030851053 | X6: -0.02291975 | Y6: 0.027766923 | Z6: -0.0047616235 | AA6: -23.021077 | AB6: 1.3966667 | AC6: 0.69 | AD6: -0.080019841 | AE6: 1.3966667 | AF6: 0.69 | AG6: 1.3966667 | AH6: 0.69 | AI6: 1.3595437 | AJ6: 0.027766923 | AK6: 6.4832043 | AL6: 8.5432272 | AM6: 6.8202309 | AN6: 9.2025896 | AO6: -0.59528567 | AP6: 13.76 | AQ6: 14.2 | AR6: 4.1522756e-07 | AS6: 5.5952806e-06 | AT6: 2.17364 | AU6: -114.29485 | AV6: 0.068090221 | AW6: 0.056574825 | AX6: 0.055469094 | AY6: 0.067221639 | AZ6: 0.062632937
A7: butterworth | B7: 42/2_LT_Fits | C7: =IF(ISNUMBER(D7),SUM(INDIRECT(_xlfn.CONCAT("e",ROW(),":e",ROW()+D7-1))),"") | E7: =AND(AX7<$C$1,averaged_runs370!AQ7<$C$1,averaged_runs126!AQ7<$C$1)*1 | F7: =IF(TRUE,SQRT(averaged_runs126!AQ7^2/2+averaged_runs370!AQ7^2/2+AX7^2*0),"") | G7: =IF(TRUE,averaged_runs126!AQ7,"") | H7: =IF(TRUE,AX7,"") | I7: =IF(TRUE,averaged_runs370!AQ7,"") | J7: c | K7: 0.72 | L7: 1.38 | M7: -0.026180828 | N7: 74.840361 | O7: 1.8997222 | P7: 0.66666667 | Q7: 1.3255067 | R7: 0.785 | S7: -0.59333333 | T7: 2.6816667 | U7: 0.89166667 | V7: 2.1569562 | W7: 0.14636481 | X7: -0.027578139 | Y7: -0.02086352 | Z7: -0.026180828 | AA7: 67.717372 | AB7: 1.9013889 | AC7: 0.67 | AD7: 1.3106647 | AE7: 0.78666667 | AF7: -0.59 | AG7: 2.445 | AH7: 0.45333333 | AI7: 1.7677282 | AJ7: -0.02086352 | AK7: 2.2070548 | AL7: 2.0965192 | AM7: 2.2786498 | AN7: 2.0889432 | AO7: 0.83237306 | AP7: 23.65 | AQ7: 24.41 | AR7: 0.41186017 | AS7: 0.91144065 | AT7: 10.1321 | AU7: 118.19697 | AV7: 0.065223945 | AW7: 0.06078721 | AX7: 0.059650588 | AY7: 0.074543325 | AZ7: 0.073521911
A8: hinge75meet | B8: 42/2_LT_Fits | C8: =IF(ISNUMBER(D8),SUM(INDIRECT(_xlfn.CONCAT("e",ROW(),":e",ROW()+D8-1))),"") | E8: =AND(AX8<$C$1,averaged_runs370!AQ8<$C$1,averaged_runs126!AQ8<$C$1)*1 | F8: =IF(TRUE,SQRT(averaged_runs126!AQ8^2/2+averaged_runs370!AQ8^2/2+AX8^2*0),"") | J8: c | K8: 9.32 | L8: 24.46 | M8: 0.015763385 | N8: 112.11336 | O8: 0.31833333 | P8: 0.43 | Q8: -0.68008242 | R8: 0.31833333 | S8: 0.43 | T8: 0.31833333 | U8: 0.43 | V8: 2.7883856 | W8: 0.060235763 | X8: 0.010480069 | Y8: 0.040835027 | Z8: 0.015763385 | AA8: 98.426825 | AB8: 0.32 | AC8: 0.43333333 | AD8: -0.9747619 | AE8: 0.32 | AF8: 0.43333333 | AG8: 0.32 | AH8: 0.43333333 | AI8: 1.9435714 | AJ8: 0.040835027 | AK8: 5.3510718 | AL8: 6.217156 | AM8: 6.1416525 | AN8: 6.5787643 | AO8: 1.2033279 | AP8: 13.58 | AQ8: 14 | AR8: 0.059934122 | AS8: 0.14606116 | AT8: 1.70804 | AU8: 187.71915 | AV8: 0.058141163 | AW8: 0.056797019 | AX8: 0.061824522 | AY8: 0.065946687 | AZ8: 0.066817359
A9: OLS_hinge75 | B9: 42/2_LT_Fits | C9: =IF(ISNUMBER(D9),SUM(INDIRECT(_xlfn.CONCAT("e",ROW(),":e",ROW()+D9-1))),"") | E9: =AND(AX9<$C$1,averaged_runs370!AQ9<$C$1,averaged_runs126!AQ9<$C$1)*1 | F9: =IF(TRUE,SQRT(averaged_runs126!AQ9^2/2+averaged_runs370!AQ9^2/2+AX9^2*0),"") | J9: c | K9: 24.86 | L9: 65.6 | M9: 0.0048653681 | N9: 57.838239 | O9: 0.95166667 | P9: 0.60833333 | Q9: -0.21398352 | R9: 0.95166667 | S9: 0.60833333 | T9: 0.95166667 | U9: 0.60833333 | V9: 2.6579148 | W9: 0.035928333 | X9: -0.0010032349 | Y9: 0.034039934 | Z9: 0.0048653681 | AA9: 19.617496 | AB9: 0.95333333 | AC9: 0.61166667 | AD9: -0.50238095 | AE9: 0.95333333 | AF9: 0.61166667 | AG9: 0.95333333 | AH9: 0.61166667 | AI9: 1.4488095 | AJ9: 0.034039934 | AK9: 7.2713466 | AL9: 8.8329425 | AM9: 8.1604185 | AN9: 9.5844505 | AO9: 0.51642694 | AP9: 13.58 | AQ9: 14 | AR9: 0.00026220634 | AS9: 0.0055938013 | AT9: 2.07002 | AU9: 80.562603 | AV9: 0.058332658 | AW9: 0.053875809 | AX9: 0.056864152 | AY9: 0.062620926 | AZ9: 0.061668857
A10: OLS_refit | B10: 42/2_LT_Fits | C10: =IF(ISNUMBER(D10),SUM(INDIRECT(_xlfn.CONCAT("e",ROW(),":e",ROW()+D10-1))),"") | E10: =AND(AX10<$C$1,averaged_runs370!AQ10<$C$1,averaged_runs126!AQ10<$C$1)*1 | F10: =IF(TRUE,SQRT(averaged_runs126!AQ10^2/2+averaged_runs370!AQ10^2/2+AX10^2*0),"") | J10: c | K10: 119.68 | L10: 131.52 | M10: -0.26133152 | N10: -2762.1689 | O10: 14.775 | P10: 15.805 | Q10: 14.536584 | R10: 14.775 | S10: 15.805 | T10: 14.775 | U10: 15.805 | V10: 14.651148 | W10: 0.031780856 | X10: -0.17730157 | Y10: -0.25446109 | Z10: -0.26133152 | AA10: -2811.8692 | AB10: 14.776667 | AC10: 15.808333 | AD10: 14.549524 | AE10: 14.776667 | AF10: 15.808333 | AG10: 14.776667 | AH10: 15.808333 | AI10: 14.549524 | AJ10: -0.25446109 | AK10: 1.3516876e-07 | AL10: 1.04804e-10 | AM10: 1.2754534e-12 | AN10: 4.0055331e-12 | AO10: -20.536532 | AP10: 13.56 | AQ10: 13.74 | AR10: 1.0710927e-16 | AS10: 1.0802109e-16 | AT10: 0.76528 | AU10: -2895.651 | AV10: 0.22157451 | AW10: 0.26720818 | AX10: 0.27638973 | AY10: 0.26840134 | AZ10: 0.27714804
A11: quartic | B11: 42/2_LT_Fits | C11: =IF(ISNUMBER(D11),SUM(INDIRECT(_xlfn.CONCAT("e",ROW(),":e",ROW()+D11-1))),"") | E11: =AND(AX11<$C$1,averaged_runs370!AQ11<$C$1,averaged_runs126!AQ11<$C$1)*1 | F11: =IF(TRUE,SQRT(averaged_runs126!AQ11^2/2+averaged_runs370!AQ11^2/2+AX11^2*0),"") | J11: c | K11: 23.8 | L11: 91.32 | M11: 0.072308043 | N11: 35.061109 | O11: -4.355 | P11: -3.9725 | Q11: -4.5017766 | R11: -4.4416667 | S11: -4.025 | T11: -4.4416667 | U11: -4.025 | V11: 5.1815851 | W11: 0.050127231 | X11: 0.031414136 | Y11: 0.073613095 | Z11: 0.072308043 | AA11: -8.6648834 | AB11: -4.3533333 | AC11: -3.9691667 | AD11: -4.527381 | AE11: -4.44 | AF11: -4.0216667 | AG11: -4.44 | AH11: -3.9166667 | AI11: 4.5933333 | AJ11: 0.073613095 | AK11: 2.8591324 | AL11: 3.0728182 | AM11: 2.7022597 | AN11: 2.3764261 | AO11: 0.58245118 | AP11: 14.112 | AQ11: 14.612 | AR11: 0.034689386 | AS11: 0.070498763 | AT11: 3.04846 | AU11: 82.125617 | AV11: 0.08376264 | AW11: 0.085811067 | AX11: 0.087840559 | AY11: 0.096859432 | AZ11: 0.09716549
A12: TheilSen_h7075 | B12: 42/2_LT_Fits | C12: =IF(ISNUMBER(D12),SUM(INDIRECT(_xlfn.CONCAT("e",ROW(),":e",ROW()+D12-1))),"") | E12: =AND(AX12<$C$1,averaged_runs370!AQ12<$C$1,averaged_runs126!AQ12<$C$1)*1 | F12: =IF(TRUE,SQRT(averaged_runs126!AQ12^2/2+averaged_runs370!AQ12^2/2+AX12^2*0),"") | G12: =IF(E12,averaged_runs126!AP11,"") | H12: =IF(E12,AW12,"") | I12: =IF(E12,averaged_runs370!AP11,"") | J12: c | K12: 33.02 | L12: 81.18 | M12: -0.017170925 | N12: -10.384011 | O12: 1.1366667 | P12: 1.9133333 | Q12: 0.76826923 | R12: 1.1366667 | S12: 1.9133333 | T12: 1.1366667 | U12: 1.9133333 | V12: 3.1660737 | W12: 0.036615849 | X12: -0.015958382 | Y12: 0.010348277 | Z12: -0.017170925 | AA12: -35.683323 | AB12: 1.1383333 | AC12: 1.9166667 | AD12: 0.48464286 | AE12: 1.1383333 | AF12: 1.9166667 | AG12: 1.1383333 | AH12: 1.9166667 | AI12: 1.8025 | AJ12: 0.010348277 | AK12: 5.4778718 | AL12: 5.7644441 | AM12: 5.7011623 | AN12: 5.3469879 | AO12: 0.48187783 | AP12: 13.58 | AQ12: 14 | AR12: 0.0043433348 | AS12: 0.027364614 | AT12: 2.1062 | AU12: 75.172942 | AV12: 0.067066302 | AW12: 0.071212754 | AX12: 0.067585356 | AY12: 0.076438489 | AZ12: 0.069149019
A13: etrend15y | B13: 42/3_ST_Fits | C13: =IF(ISNUMBER(D13),SUM(INDIRECT(_xlfn.CONCAT("e",ROW(),":e",ROW()+D13-1))),"") | D13: 15 | E13: =AND(AX13<$C$1,averaged_runs370!AQ13<$C$1,averaged_runs126!AQ13<$C$1)*1 | F13: =IF(TRUE,SQRT(averaged_runs126!AQ13^2/2+averaged_runs370!AQ13^2/2+AX13^2*0),"") | G13: =IF(E13,averaged_runs126!AQ13,"") | H13: =IF(E13,AX13,"") | I13: =IF(E13,averaged_runs370!AQ13,"") | J13: c | K13: 5.74 | L13: 31.54 | M13: 0.0064456429 | N13: 126.55328 | O13: 0.16805556 | P13: -0.6725 | Q13: -0.22162882 | R13: -0.56666667 | S13: -1.4633333 | T13: 0.19833333 | U13: -0.875 | V13: 1.9935565 | W13: 0.058315207 | X13: -0.0018114127 | Y13: 0.0088992033 | Z13: 0.0064456429 | AA13: 93.03125 | AB13: 0.16972222 | AC13: -0.66916667 | AD13: -0.29994643 | AE13: -0.565 | AF13: -1.46 | AG13: 0.315 | AH13: -1.1966667 | AI13: 1.3464028 | AJ13: 0.0088992033 | AK13: 4.5582682 | AL13: 3.9348633 | AM13: 5.0718089 | AN13: 5.2382529 | AO13: 1.1739444 | AP13: 18.43 | AQ13: 19.11 | AR13: 0.12771397 | AS13: 0.22792735 | AT13: 5.71256 | AU13: 266.48538 | AV13: 0.066750263 | AW13: 0.057491124 | AX13: 0.053863839 | AY13: 0.074466764 | AZ13: 0.07144138
A14: etrend30y | B14: 42/3_ST_Fits | C14: =IF(ISNUMBER(D14),SUM(INDIRECT(_xlfn.CONCAT("e",ROW(),":e",ROW()+D14-1))),"") | E14: =AND(AX14<$C$1,averaged_runs370!AQ14<$C$1,averaged_runs126!AQ14<$C$1)*1 | F14: =IF(TRUE,SQRT(averaged_runs126!AQ14^2/2+averaged_runs370!AQ14^2/2+AX14^2*0),"") | G14: =IF(E14,averaged_runs126!AQ14,"") | H14: =IF(E14,AX14,"") | I14: =IF(E14,averaged_runs370!AQ14,"") | J14: c | K14: 4.36 | L14: 30.12 | M14: 0.0061584544 | N14: 155.58585 | O14: 0.7975 | P14: -0.84416667 | Q14: -0.56058608 | R14: 0.695 | S14: -0.885 | T14: 0.9 | U14: -0.80333333 | V14: 2.3342628 | W14: 0.044016723 | X14: -0.0048702144 | Y14: 0.020527255 | Z14: 0.0061584544 | AA14: 109.52429 | AB14: 0.79916667 | AC14: -0.84083333 | AD14: -0.60728175 | AE14: 0.69666667 | AF14: -0.88166667 | AG14: 0.815 | AH14: -0.8 | AI14: 1.4365278 | AJ14: 0.020527255 | AK14: 5.6717643 | AL14: 4.753359 | AM14: 6.3213685 | AN14: 6.6494513 | AO14: 1.4623069 | AP14: 14.712 | AQ14: 15.332 | AR14: 0.15992458 | AS14: 0.20983237 | AT14: 2.97912 | AU14: 310.00907 | AV14: 0.052925463 | AW14: 0.0432086 | AX14: 0.041947524 | AY14: 0.060788524 | AZ14: 0.058785041
A15: etrend30y_3CS | B15: 42/3_ST_Fits | C15: =IF(ISNUMBER(D15),SUM(INDIRECT(_xlfn.CONCAT("e",ROW(),":e",ROW()+D15-1))),"") | E15: =AND(AX15<$C$1,averaged_runs370!AQ15<$C$1,averaged_runs126!AQ15<$C$1)*1 | F15: =IF(TRUE,SQRT(averaged_runs126!AQ15^2/2+averaged_runs370!AQ15^2/2+AX15^2*0),"") | G15: =IF(E15,averaged_runs126!AQ15,"") | H15: =IF(E15,AX15,"") | I15: =IF(E15,averaged_runs370!AQ15,"") | J15: c | K15: 12.12 | L15: 55.54 | M15: -0.01690544 | N15: 110.73322 | O15: 0.7975 | P15: -0.84416667 | Q15: -0.11784951 | R15: 0.695 | S15: -0.885 | T15: 0.9 | U15: -0.80333333 | V15: 2.3549413 | W15: 0.044016723 | X15: -0.014770282 | Y15: 0.020527255 | Z15: -0.01690544 | AA15: 84.449098 | AB15: 0.79916667 | AC15: -0.84083333 | AD15: -0.17309524 | AE15: 0.69666667 | AF15: -0.88166667 | AG15: 0.815 | AH15: -0.8 | AI15: 1.2024603 | AJ15: 0.020527255 | AK15: 5.6717643 | AL15: 4.753359 | AM15: 6.3213685 | AN15: 6.6494513 | AO15: 1.2507379 | AP15: 14.692 | AQ15: 15.312 | AR15: 0.066154471 | AS15: 0.096825946 | AT15: 3.14716 | AU15: 265.15643 | AV15: 0.06172704 | AW15: 0.064945411 | AX15: 0.041947524 | AY15: 0.070778457 | AZ15: 0.058785041
A16: lowess1dg20wnc | B16: 42/3_ST_Fits | C16: =IF(ISNUMBER(D16),SUM(INDIRECT(_xlfn.CONCAT("e",ROW(),":e",ROW()+D16-1))),"") | E16: =AND(AX16<$C$1,averaged_runs370!AQ16<$C$1,averaged_runs126!AQ16<$C$1)*1 | F16: =IF(TRUE,SQRT(averaged_runs126!AQ16^2/2+averaged_runs370!AQ16^2/2+AX16^2*0),"") | G16: =IF(E16,averaged_runs126!AQ16,"") | H16: =IF(E16,AX16,"") | I16: =IF(E16,averaged_runs370!AQ16,"") | J16: c | K16: 0.96 | L16: 8.16 | M16: 0.00093151457 | N16: 155.67604 | O16: 0.73333333 | P16: -0.59555556 | Q16: -0.48592796 | R16: 0.73333333 | S16: -0.66833333 | T16: 0.73333333 | U16: -0.66833333 | V16: 2.2239364 | W16: 0.060448442 | X16: -0.010659427 | Y16: 0.027772774 | Z16: 0.00093151457 | AA16: 108.7593 | AB16: 0.735 | AC16: -0.59222222 | AD16: -0.62634921 | AE16: 0.735 | AF16: -0.665 | AG16: 0.735 | AH16: -0.665 | AI16: 1.3765873 | AJ16: 0.027772774 | AK16: 6.4334272 | AL16: 6.1421613 | AM16: 7.5931658 | AN16: 8.6232285 | AO16: 1.4708011 | AP16: 13.86 | AQ16: 14.4 | AR16: 0.39904133 | AS16: 0.50120509 | AT16: 2.52608 | AU16: 339.75507 | AV16: 0.052121951 | AW16: 0.042915696 | AX16: 0.039870844 | AY16: 0.058404922 | AZ16: 0.054357272
A17: lowess1dt10wnc | B17: 42/3_ST_Fits | C17: =IF(ISNUMBER(D17),SUM(INDIRECT(_xlfn.CONCAT("e",ROW(),":e",ROW()+D17-1))),"") | E17: =AND(AX17<$C$1,averaged_runs370!AQ17<$C$1,averaged_runs126!AQ17<$C$1)*1 | F17: =IF(TRUE,SQRT(averaged_runs126!AQ17^2/2+averaged_runs370!AQ17^2/2+AX17^2*0),"") | G17: =IF(E17,averaged_runs126!AQ17,"") | H17: =IF(E17,AX17,"") | I17: =IF(E17,averaged_runs370!AQ17,"") | J17: c | K17: 84.36 | L17: 149.36 | M17: 0.0055550459 | N17: -223.65601 | O17: 0.096388889 | P17: -0.42694444 | Q17: -0.14398077 | R17: -1.7316667 | S17: -2.9283333 | T17: -0.32166667 | U17: -0.42 | V17: 2.1432745 | W17: 0.047098951 | X17: -0.0013922827 | Y17: 0.0050643843 | Z17: 0.0055550459 | AA17: -337.57652 | AB17: 0.098055556 | AC17: -0.42361111 | AD17: -0.27588492 | AE17: -1.73 | AF17: -2.925 | AG17: -0.2 | AH17: -0.98166667 | AI17: 1.4114008 | AJ17: 0.0050643843 | AK17: 4.6377025 | AL17: 2.8523035 | AM17: 5.3028597 | AN17: 3.6468684 | AO17: -1.4098966 | AP17: 25.686 | AQ17: 26.686 | AR17: 5.0615657e-10 | AS17: 6.1989859e-07 | AT17: 10.37252 | AU17: -325.68612 | AV17: 0.093159246 | AW17: 0.084954115 | AX17: 0.080979798 | AY17: 0.094299711 | AZ17: 0.090792358
A18: lowess1dt20wAR | B18: 42/3_ST_Fits | C18: =IF(ISNUMBER(D18),SUM(INDIRECT(_xlfn.CONCAT("e",ROW(),":e",ROW()+D18-1))),"") | E18: =AND(AX18<$C$1,averaged_runs370!AQ18<$C$1,averaged_runs126!AQ18<$C$1)*1 | F18: =IF(TRUE,SQRT(averaged_runs126!AQ18^2/2+averaged_runs370!AQ18^2/2+AX18^2*0),"") | G18: =IF(E18,averaged_runs126!AQ18,"") | H18: =IF(E18,AX18,"") | I18: =IF(E18,averaged_runs370!AQ18,"") | J18: c | K18: 64.72 | L18: 133.44 | M18: 0.0065469648 | N18: -32.270383 | O18: 0.30694444 | P18: -0.80083333 | Q18: -0.24130647 | R18: -0.22 | S18: -1.615 | T18: 0.27333333 | U18: -1.2066667 | V18: 1.9373424 | W18: 0.039862296 | X18: -0.002007214 | Y18: 0.0089164269 | Z18: 0.0065469648 | AA18: -242.34283 | AB18: 0.30861111 | AC18: -0.7975 | AD18: -0.29665675 | AE18: -0.21833333 | AF18: -1.6116667 | AG18: 0.46666667 | AH18: -1.365 | AI18: 1.386994 | AJ18: 0.0089164269 | AK18: 6.5777215 | AL18: 4.239953 | AM18: 7.5396354 | AN18: 5.89087 | AO18: -0.019441413 | AP18: 18.456 | AQ18: 19.136 | AR18: 2.0621461e-05 | AS18: 0.00048719662 | AT18: 5.55908 | AU18: -4.4909665 | AV18: 0.065329565 | AW18: 0.055764974 | AX18: 0.05273546 | AY18: 0.072408393 | AZ18: 0.069881898
A19: lowess1dt20wARMA | B19: 42/3_ST_Fits | C19: =IF(ISNUMBER(D19),SUM(INDIRECT(_xlfn.CONCAT("e",ROW(),":e",ROW()+D19-1))),"") | E19: =AND(AX19<$C$1,averaged_runs370!AQ19<$C$1,averaged_runs126!AQ19<$C$1)*1 | F19: =IF(TRUE,SQRT(averaged_runs126!AQ19^2/2+averaged_runs370!AQ19^2/2+AX19^2*0),"") | G19: =IF(E19,averaged_runs126!AQ19,"") | H19: =IF(E19,AX19,"") | I19: =IF(E19,averaged_runs370!AQ19,"") | J19: c | K19: 51.54 | L19: 117.04 | M19: 0.0065469648 | N19: 20.821307 | O19: 0.30694444 | P19: -0.80361111 | Q19: -0.24061813 | R19: -0.21833333 | S19: -1.6166667 | T19: 0.27166667 | U19: -1.2066667 | V19: 1.9358802 | W19: 0.035920503 | X19: -0.0012636155 | Y19: 0.0089164269 | Z19: 0.0065469648 | AA19: -140.53755 | AB19: 0.30861111 | AC19: -0.80027778 | AD19: -0.29581349 | AE19: -0.21666667 | AF19: -1.6133333 | AG19: 0.46833333 | AH19: -1.365 | AI19: 1.3852976 | AJ19: 0.0089164269 | AK19: 6.2929684 | AL19: 4.1973253 | AM19: 7.2535451 | AN19: 5.9460596 | AO19: 0.36072251 | AP19: 18.456 | AQ19: 19.136 | AR19: 0.00021526493 | AS19: 0.0019562038 | AT19: 5.50272 | AU19: 77.862888 | AV19: 0.065678264 | AW19: 0.055764974 | AX19: 0.05273546 | AY19: 0.072408393 | AZ19: 0.069881898
A20: lowess1dt20wnc | B20: 42/3_ST_Fits | C20: =IF(ISNUMBER(D20),SUM(INDIRECT(_xlfn.CONCAT("e",ROW(),":e",ROW()+D20-1))),"") | E20: =AND(AX20<$C$1,averaged_runs370!AQ20<$C$1,averaged_runs126!AQ20<$C$1)*1 | F20: =IF(TRUE,SQRT(averaged_runs126!AQ20^2/2+averaged_runs370!AQ20^2/2+AX20^2*0),"") | G20: =IF(E20,averaged_runs126!AQ20,"") | H20: =IF(E20,AX20,"") | I20: =IF(E20,averaged_runs370!AQ20,"") | J20: c | K20: 14.06 | L20: 54.98 | M20: 0.0065469648 | N20: 104.25212 | O20: 0.31194444 | P20: -0.79611111 | Q20: -0.23821657 | R20: -0.21333333 | S20: -1.6083333 | T20: 0.27666667 | U20: -1.1983333 | V20: 1.9332643 | W20: 0.057217489 | X20: -0.002007214 | Y20: 0.0089164269 | Z20: 0.0065469648 | AA20: 23.5685 | AB20: 0.31361111 | AC20: -0.79277778 | AD20: -0.29402778 | AE20: -0.21166667 | AF20: -1.605 | AG20: 0.47333333 | AH20: -1.3566667 | AI20: 1.3830952 | AJ20: 0.0089164269 | AK20: 5.591609 | AL20: 4.0865727 | AM20: 6.4102103 | AN20: 5.7931093 | AO20: 1.0917347 | AP20: 18.456 | AQ20: 19.136 | AR20: 0.028463693 | AS20: 0.066573808 | AT20: 5.55908 | AU20: 252.19073 | AV20: 0.065329565 | AW20: 0.055764974 | AX20: 0.05273546 | AY20: 0.072408393 | AZ20: 0.069881898
A21: lowess1dt26wnc | B21: 42/3_ST_Fits | C21: =IF(ISNUMBER(D21),SUM(INDIRECT(_xlfn.CONCAT("e",ROW(),":e",ROW()+D21-1))),"") | E21: =AND(AX21<$C$1,averaged_runs370!AQ21<$C$1,averaged_runs126!AQ21<$C$1)*1 | F21: =IF(TRUE,SQRT(averaged_runs126!AQ21^2/2+averaged_runs370!AQ21^2/2+AX21^2*0),"") | G21: =IF(E21,averaged_runs126!AQ21,"") | H21: =IF(E21,AX21,"") | I21: =IF(E21,averaged_runs370!AQ21,"") | J21: c | K21: 4.06 | L21: 21.7 | M21: 0.0064372505 | N21: 141.15802 | O21: 0.47166667 | P21: -0.93916667 | Q21: -0.26412241 | R21: 0.29 | S21: -1.39 | T21: 0.55833333 | U21: -1.39 | V21: 1.9554952 | W21: 0.059796063 | X21: -0.0027901722 | Y21: 0.011639617 | Z21: 0.0064372505 | AA21: 70.103827 | AB21: 0.47333333 | AC21: -0.93583333 | AD21: -0.30401786 | AE21: 0.29166667 | AF21: -1.3866667 | AG21: 0.655 | AH21: -1.3866667 | AI21: 1.446756 | AJ21: 0.011639617 | AK21: 5.7488291 | AL21: 4.4351053 | AM21: 6.9179238 | AN21: 6.6542755 | AO21: 1.3521901 | AP21: 16.916 | AQ21: 17.556 | AR21: 0.18590156 | AS21: 0.29528436 | AT21: 4.43022 | AU21: 312.35592 | AV21: 0.057659536 | AW21: 0.046685189 | AX21: 0.044683593 | AY21: 0.065837317 | AZ21: 0.064107086
A22: lowess1dt30wnc | B22: 42/3_ST_Fits | C22: =IF(ISNUMBER(D22),SUM(INDIRECT(_xlfn.CONCAT("e",ROW(),":e",ROW()+D22-1))),"") | E22: =AND(AX22<$C$1,averaged_runs370!AQ22<$C$1,averaged_runs126!AQ22<$C$1)*1 | F22: =IF(TRUE,SQRT(averaged_runs126!AQ22^2/2+averaged_runs370!AQ22^2/2+AX22^2*0),"") | G22: =IF(E22,averaged_runs126!AQ22,"") | H22: =IF(E22,AX22,"") | I22: =IF(E22,averaged_runs370!AQ22,"") | J22: c | K22: 2.4 | L22: 12 | M22: 0.0063655982 | N22: 151.82624 | O22: 0.50333333 | P22: -0.80833333 | Q22: -0.37961691 | R22: 0.41833333 | S22: -1.005 | T22: 0.50833333 | U22: -1.005 | V22: 2.0770233 | W22: 0.061047595 | X22: -0.0033852613 | Y22: 0.013780747 | Z22: 0.0063655982 | AA22: 87.124523 | AB22: 0.505 | AC22: -0.805 | AD22: -0.39779762 | AE22: 0.42 | AF22: -1.0016667 | AG22: 0.59 | AH22: -1.0016667 | AI22: 1.4339484 | AJ22: 0.013780747 | AK22: 5.7334875 | AL22: 4.8830396 | AM22: 7.0258734 | AN22: 7.0534246 | AO22: 1.4341846 | AP22: 15.688 | AQ22: 16.248 | AR22: 0.31751812 | AS22: 0.44886313 | AT22: 3.91888 | AU22: 331.29665 | AV22: 0.054370313 | AW22: 0.043250785 | AX22: 0.041794976 | AY22: 0.062943905 | AZ22: 0.061476921
A23: lowess1dt36wnc | B23: 42/3_ST_Fits | E23: =AND(AX23<$C$1,averaged_runs370!AQ23<$C$1,averaged_runs126!AQ23<$C$1)*1 | F23: =IF(TRUE,SQRT(averaged_runs126!AQ23^2/2+averaged_runs370!AQ23^2/2+AX23^2*0),"") | G23: =IF(E23,averaged_runs126!AQ23,"") | H23: =IF(E23,AX23,"") | I23: =IF(E23,averaged_runs370!AQ23,"") | J23: c | K23: 0.96 | L23: 4.8 | M23: 0.0062466096 | N23: 159.50953 | O23: 0.59833333 | P23: -0.7725 | Q23: -0.46588675 | R23: 0.56 | S23: -0.78666667 | T23: 0.63666667 | U23: -0.75833333 | V23: 2.1420977 | W23: 0.062465716 | X23: -0.0043984581 | Y23: 0.017274168 | Z23: 0.0062466096 | AA23: 103.47717 | AB23: 0.6 | AC23: -0.76916667 | AD23: -0.49906746 | AE23: 0.56166667 | AF23: -0.78333333 | AG23: 0.63833333 | AH23: -0.755 | AI23: 1.4389881 | AJ23: 0.017274168 | AK23: 5.7757386 | AL23: 5.0681913 | AM23: 7.0716206 | AN23: 7.1803632 | AO23: 1.4971712 | AP23: 14.924 | AQ23: 15.524 | AR23: 0.48164843 | AS23: 0.64204593 | AT23: 3.36506 | AU23: 345.84654 | AV23: 0.051270553 | AW23: 0.040488592 | AX23: 0.039691137 | AY23: 0.060011427 | AZ23: 0.058660319
A24: lowess2dt20wnc | B24: 42/3_ST_Fits | E24: =AND(AX24<$C$1,averaged_runs370!AQ24<$C$1,averaged_runs126!AQ24<$C$1)*1 | F24: =IF(TRUE,SQRT(averaged_runs126!AQ24^2/2+averaged_runs370!AQ24^2/2+AX24^2*0),"") | G24: =IF(E24,averaged_runs126!AQ24,"") | H24: =IF(E24,AX24,"") | I24: =IF(E24,averaged_runs370!AQ24,"") | J24: c | K24: 28.46 | L24: 83.86 | M24: 0.0061081609 | N24: 24.299721 | O24: 0.17402778 | P24: -0.12083333 | Q24: -0.2059101 | R24: -1.5383333 | S24: -2.6083333 | T24: -0.34 | U24: 0.40166667 | V24: 2.2045483 | W24: 0.07171752 | X24: -0.0011925565 | Y24: 0.0046826443 | Z24: 0.0061081609 | AA24: -16.75698 | AB24: 0.17569444 | AC24: -0.1175 | AD24: -0.32756151 | AE24: -1.5366667 | AF24: -2.605 | AG24: -0.13833333 | AH24: -0.49666667 | AI24: 1.4082123 | AJ24: 0.0046826443 | AK24: 4.1700241 | AL24: 2.9534496 | AM24: 4.4340287 | AN24: 3.5988304 | AO24: 0.48448134 | AP24: 25.802 | AQ24: 26.862 | AR24: 0.0028841847 | AS24: 0.0094426705 | AT24: 10.64588 | AU24: 111.91519 | AV24: 0.095109779 | AW24: 0.087866901 | AX24: 0.082045576 | AY24: 0.09679455 | AZ24: 0.091586616
A25: lowess2dt30wnc | B25: 42/3_ST_Fits | E25: =AND(AX25<$C$1,averaged_runs370!AQ25<$C$1,averaged_runs126!AQ25<$C$1)*1 | F25: =IF(TRUE,SQRT(averaged_runs126!AQ25^2/2+averaged_runs370!AQ25^2/2+AX25^2*0),"") | G25: =IF(E25,averaged_runs126!AQ25,"") | H25: =IF(E25,AX25,"") | I25: =IF(E25,averaged_runs370!AQ25,"") | J25: c | K25: 5.16 | L25: 25.34 | M25: 0.0064682823 | N25: 102.8406 | O25: 0.31013889 | P25: -0.84777778 | Q25: -0.19011218 | R25: -0.90333333 | S25: -2.355 | T25: 0.205 | U25: -1.2633333 | V25: 2.0642241 | W25: 0.079367101 | X25: -0.0010646903 | Y25: 0.0052596196 | Z25: 0.0064682823 | AA25: 64.571762 | AB25: 0.31180556 | AC25: -0.84444444 | AD25: -0.28060516 | AE25: -0.90166667 | AF25: -2.3516667 | AG25: 0.44833333 | AH25: -1.2333333 | AI25: 1.4309821 | AJ25: 0.0052596196 | AK25: 4.5676381 | AL25: 3.5379881 | AM25: 4.9860641 | AN25: 4.5503645 | AO25: 1.0106084 | AP25: 20.992 | AQ25: 21.732 | AR25: 0.11818897 | AS25: 0.2445794 | AT25: 7.68258 | AU25: 233.45055 | AV25: 0.080047592 | AW25: 0.069185616 | AX25: 0.064336622 | AY25: 0.083103998 | AZ25: 0.07912277
A26: min_month_proj | B26: 42/3_ST_Fits | C26: =IF(ISNUMBER(D26),SUM(INDIRECT(_xlfn.CONCAT("e",ROW(),":e",ROW()+D26-1))),"") | E26: =AND(AX26<$C$1,averaged_runs370!AQ26<$C$1,averaged_runs126!AQ26<$C$1)*1 | F26: =IF(TRUE,SQRT(averaged_runs126!AQ26^2/2+averaged_runs370!AQ26^2/2+AX26^2*0),"") | G26: =IF(E26,averaged_runs126!AQ26,"") | H26: =IF(E26,AX26,"") | I26: =IF(E26,averaged_runs370!AQ26,"") | J26: c | K26: 0.42 | L26: 2.88 | M26: 0.035100595 | N26: 76.367372 | O26: -0.63861111 | P26: 0.20472222 | Q26: -0.86777625 | R26: -1.8833333 | S26: -2.3416667 | T26: -1.4716667 | U26: 1.1866667 | V26: 3.4206816 | W26: 0.15075796 | X26: 0.037441422 | Y26: 0.017098952 | Z26: 0.035100595 | AA26: 68.55314 | AB26: -0.63694444 | AC26: 0.20805556 | AD26: -0.88814484 | AE26: -1.8816667 | AF26: -2.3383333 | AG26: -1.4883333 | AH26: 1.2516667 | AI26: 1.7632639 | AJ26: 0.017098952 | AK26: 2.7060855 | AL26: 2.3313213 | AM26: 2.9042422 | AN26: 2.4763117 | AO26: 0.69850672 | AP26: 19.696 | AQ26: 20.276 | AR26: 0.64591008 | AS26: 0.76698691 | AT26: 10.68856 | AU26: 155.06849 | AV26: 0.10754886 | AW26: 0.10545281 | AX26: 0.095759538 | AY26: 0.11475753 | AZ26: 0.10564208
A27: opt_clim_norm | B27: 42/3_ST_Fits | C27: =IF(ISNUMBER(D27),SUM(INDIRECT(_xlfn.CONCAT("e",ROW(),":e",ROW()+D27-1))),"") | E27: =AND(AX27<$C$1,averaged_runs370!AQ27<$C$1,averaged_runs126!AQ27<$C$1)*1 | F27: =IF(TRUE,SQRT(averaged_runs126!AQ27^2/2+averaged_runs370!AQ27^2/2+AX27^2*0),"") | G27: =IF(E27,averaged_runs126!AQ27,"") | H27: =IF(E27,AX27,"") | I27: =IF(E27,averaged_runs370!AQ27,"") | J27: c | K27: 40.38 | L27: 87.66 | M27: -0.017833769 | N27: -151740.44 | O27: 0.27272222 | P27: 0.77527778 | Q27: 0.50787956 | R27: -2.925 | S27: -2.1033333 | T27: -0.29166667 | U27: 2.0366667 | V27: 2.9593375 | W27: 0.053792618 | X27: -0.017364035 | Y27: -0.013659664 | Z27: -0.017833769 | AA27: -219855.49 | AB27: 0.27438889 | AC27: 0.77861111 | AD27: 0.41931179 | AE27: -2.9233333 | AF27: -2.1 | AG27: 0.35333333 | AH27: 1.095 | AI27: 1.4791888 | AJ27: -0.013659664 | AK27: 3.404908 | AL27: 3.4966853 | AM27: 3.0579469 | AN27: 3.3310947 | AO27: -2154.9752 | AP27: 31.13 | AQ27: 31.93 | AR27: 3.026292e-12 | AS27: 0.00076472896 | AT27: 14.8872 | AU27: -497799.28 | AV27: 0.088321012 | AW27: 0.098170979 | AX27: 0.090188983 | AY27: 0.10654135 | AZ27: 0.098786286
A28: cubic_spline | B28: 42/4_GAM_AR1 | C28: =IF(ISNUMBER(D28),SUM(INDIRECT(_xlfn.CONCAT("e",ROW(),":e",ROW()+D28-1))),"") | D28: 3 | E28: =AND(AX28<$C$1,averaged_runs370!AQ28<$C$1,averaged_runs126!AQ28<$C$1)*1 | F28: =IF(TRUE,SQRT(averaged_runs126!AQ28^2/2+averaged_runs370!AQ28^2/2+AX28^2*0),"") | G28: =IF(E28,averaged_runs126!AQ28,"") | H28: =IF(E28,AX28,"") | I28: =IF(E28,averaged_runs370!AQ28,"") | J28: c | K28: 1.74 | L28: 8.44 | M28: 0.0048617835 | N28: 116.84237 | O28: 1.645 | P28: -1.77 | Q28: -0.21937042 | R28: 1.3716667 | S28: -1.8633333 | T28: 1.7166667 | U28: -1.8633333 | V28: 3.0007384 | W28: 0.086301195 | X28: -0.0012391368 | Y28: 0.02946526 | Z28: 0.0048617835 | AA28: 100.36619 | AB28: 1.6466667 | AC28: -1.7666667 | AD28: -0.28441468 | AE28: 1.3733333 | AF28: -1.86 | AG28: 1.805 | AH28: -1.86 | AI28: 1.5650099 | AJ28: 0.02946526 | AK28: 3.2396574 | AL28: 3.4642471 | AM28: 3.6392056 | AN28: 3.9416338 | AO28: 0.98519145 | AP28: 17.004 | AQ28: 17.604 | AR28: 0.1931412 | AS28: 0.50414041 | AT28: 8.53532 | AU28: 207.8754 | AV28: 0.092255884 | AW28: 0.064882051 | AX28: 0.061381024 | AY28: 0.080484621 | AZ28: 0.078279523
A29: GAM_AR0 | B29: 42/4_GAM_AR1 | C29: =IF(ISNUMBER(D29),SUM(INDIRECT(_xlfn.CONCAT("e",ROW(),":e",ROW()+D29-1))),"") | E29: =AND(AX29<$C$1,averaged_runs370!AQ29<$C$1,averaged_runs126!AQ29<$C$1)*1 | F29: =IF(TRUE,SQRT(averaged_runs126!AQ29^2/2+averaged_runs370!AQ29^2/2+AX29^2*0),"") | G29: =IF(E29,averaged_runs126!AQ29,"") | H29: =IF(E29,AX29,"") | I29: =IF(E29,averaged_runs370!AQ29,"") | J29: c | K29: 8.1 | L29: 37 | M29: 0.0081647204 | N29: 155.88826 | O29: 0.56 | P29: -1.1005556 | Q29: -0.58364011 | R29: 0.39 | S29: -1.24 | T29: 0.59333333 | U29: -1.24 | V29: 2.2921056 | W29: 0.04992551 | X29: -0.0032275627 | Y29: 0.020900391 | Z29: 0.0081647204 | AA29: 114.69966 | AB29: 0.56166667 | AC29: -1.0972222 | AD29: -0.61386905 | AE29: 0.39166667 | AF29: -1.2366667 | AG29: 0.46333333 | AH29: -1.2366667 | AI29: 1.5047024 | AJ29: 0.020900391 | AK29: 5.2005171 | AL29: 5.2093882 | AM29: 6.5199675 | AN29: 6.5134492 | AO29: 1.2174595 | AP29: 14.86 | AQ29: 15.46 | AR29: 0.051039638 | AS29: 0.13507084 | AT29: 5.41652 | AU29: 258.10141 | AV29: 0.067433109 | AW29: 0.043465024 | AX29: 0.042694875 | AY29: 0.061894791 | AZ29: 0.0603943
A30: GAM_AR1 | B30: 42/4_GAM_AR1 | C30: =IF(ISNUMBER(D30),SUM(INDIRECT(_xlfn.CONCAT("e",ROW(),":e",ROW()+D30-1))),"") | E30: =AND(AX30<$C$1,averaged_runs370!AQ30<$C$1,averaged_runs126!AQ30<$C$1)*1 | F30: =IF(TRUE,SQRT(averaged_runs126!AQ30^2/2+averaged_runs370!AQ30^2/2+AX30^2*0),"") | G30: =IF(E30,averaged_runs126!AQ30,"") | H30: =IF(E30,AX30,"") | I30: =IF(E30,averaged_runs370!AQ30,"") | J30: c | K30: 11.1 | L30: 32.44 | M30: 0.0015236109 | N30: 140.95416 | O30: 0.53833333 | P30: -0.81555556 | Q30: -0.47400488 | R30: 0.37 | S30: -1.035 | T30: 0.61166667 | U30: -0.93166667 | V30: 2.060079 | W30: 0.053040079 | X30: -0.014846035 | Y30: 0.026461332 | Z30: 0.0015236109 | AA30: 118.21301 | AB30: 0.54 | AC30: -0.81222222 | AD30: -0.59315476 | AE30: 0.37166667 | AF30: -1.0316667 | AG30: 0.55333333 | AH30: -0.98166667 | AI30: 1.4208135 | AJ30: 0.026461332 | AK30: 4.9524776 | AL30: 4.9452141 | AM30: 5.7676965 | AN30: 5.7060074 | AO30: 1.1533996 | AP30: 16.66 | AQ30: 17.5 | AR30: 0.067105862 | AS30: 0.11476915 | AT30: 6.09796 | AU30: 244.52072 | AV30: 0.062320386 | AW30: 0.048475209 | AX30: 0.04219643 | AY30: 0.064201267 | AZ30: 0.056507981
A31: Kal_flexLin | B31: 42/5_Kalman | C31: =IF(ISNUMBER(D31),SUM(INDIRECT(_xlfn.CONCAT("e",ROW(),":e",ROW()+D31-1))),"") | D31: 4 | E31: =AND(AX31<$C$1,averaged_runs370!AQ31<$C$1,averaged_runs126!AQ31<$C$1)*1 | F31: =IF(TRUE,SQRT(averaged_runs126!AQ31^2/2+averaged_runs370!AQ31^2/2+AX31^2*0),"") | G31: =IF(E31,averaged_runs126!AQ31,"") | H31: =IF(E31,AX31,"") | I31: =IF(E31,averaged_runs370!AQ31,"") | J31: c | K31: 0.74 | L31: 9.24 | M31: 0.0063357361 | N31: 156.62857 | O31: 0.625 | P31: -0.6825 | Q31: -0.35670177 | R31: 0.425 | S31: -0.9 | T31: 0.73333333 | U31: -0.9 | V31: 1.8750995 | W31: 0.051980416 | X31: -0.003221281 | Y31: 0.014923192 | Z31: 0.0063357361 | AA31: 119.98712 | AB31: 0.62666667 | AC31: -0.67916667 | AD31: -0.41162698 | AE31: 0.42666667 | AF31: -0.89666667 | AG31: 0.66666667 | AH31: -0.89666667 | AI31: 1.4117857 | AJ31: 0.014923192 | AK31: 5.0633357 | AL31: 4.6589477 | AM31: 6.244638 | AN31: 5.8580198 | AO31: 1.5469582 | AP31: 16.62 | AQ31: 17.3 | AR31: 0.41714933 | AS31: 0.58902631 | AT31: 4.65244 | AU31: 357.34734 | AV31: 0.051369132 | AW31: 0.042451647 | AX31: 0.042115562 | AY31: 0.061185055 | AZ31: 0.060267452
A32: Kal_flexLin_ocn | B32: 42/5_Kalman | C32: =IF(ISNUMBER(D32),SUM(INDIRECT(_xlfn.CONCAT("e",ROW(),":e",ROW()+D32-1))),"") | E32: =AND(AX32<$C$1,averaged_runs370!AQ32<$C$1,averaged_runs126!AQ32<$C$1)*1 | F32: =IF(TRUE,SQRT(averaged_runs126!AQ32^2/2+averaged_runs370!AQ32^2/2+AX32^2*0),"") | G32: =IF(E32,averaged_runs126!AQ32,"") | H32: =IF(E32,AX32,"") | I32: =IF(E32,averaged_runs370!AQ32,"") | J32: c | K32: 7.38 | L32: 69.1 | M32: 0.045428845 | N32: 98.861646 | O32: -1.0508333 | P32: -3.1011111 | Q32: -2.612236 | R32: -1.2433333 | S32: -3.4233333 | T32: -1.2433333 | U32: -3.4233333 | V32: 3.714743 | W32: 0.047881903 | X32: 0.013218547 | Y32: 0.070914948 | Z32: 0.045428845 | AA32: 58.136781 | AB32: -1.0491667 | AC32: -3.0977778 | AD32: -2.8033175 | AE32: -1.2416667 | AF32: -3.42 | AG32: -1.1466667 | AH32: -3.22 | AI32: 2.8968889 | AJ32: 0.070914948 | AK32: 5.3810139 | AL32: 3.6054517 | AM32: 6.3865484 | AN32: 3.1058783 | AO32: 1.2630256 | AP32: 16.02 | AQ32: 16.78 | AR32: 0.061336879 | AS32: 0.1175849 | AT32: 4.9037 | AU32: 291.75892 | AV32: 0.060955028 | AW32: 0.066526762 | AX32: 0.071534955 | AY32: 0.078925749 | AZ32: 0.082879374
A33: Kalman_RW | B33: 42/5_Kalman | C33: =IF(ISNUMBER(D33),SUM(INDIRECT(_xlfn.CONCAT("e",ROW(),":e",ROW()+D33-1))),"") | E33: =AND(AX33<$C$1,averaged_runs370!AQ33<$C$1,averaged_runs126!AQ33<$C$1)*1 | F33: =IF(TRUE,SQRT(averaged_runs126!AQ33^2/2+averaged_runs370!AQ33^2/2+AX33^2*0),"") | G33: =IF(E33,averaged_runs126!AQ33,"") | H33: =IF(E33,AX33,"") | I33: =IF(E33,averaged_runs370!AQ33,"") | J33: c | K33: 1.42 | L33: 18.5 | M33: -0.041421251 | N33: 121.18618 | O33: 2.8008333 | P33: 1.9208333 | Q33: 2.3179815 | R33: 2.3166667 | S33: 1.135 | T33: 3.285 | U33: 2.7233333 | V33: 2.8092305 | W33: 0.053934804 | X33: -0.027867044 | Y33: -0.031453992 | Z33: -0.041421251 | AA33: 93.727483 | AB33: 2.8025 | AC33: 1.9241667 | AD33: 2.2760813 | AE33: 2.3183333 | AF33: 1.1383333 | AG33: 3.2416667 | AH33: 2.49 | AI33: 2.3985615 | AJ33: -0.031453992 | AK33: 3.4070366 | AL33: 4.4265836 | AM33: 3.9795279 | AN33: 5.4729948 | AO33: 1.3576527 | AP33: 18.144 | AQ33: 18.744 | AR33: 0.2348084 | AS33: 0.3761324 | AT33: 6.1206 | AU33: 313.61777 | AV33: 0.060919525 | AW33: 0.062102483 | AX33: 0.060914117 | AY33: 0.074492011 | AZ33: 0.073007786
A34: Kalman_RW_ocn | B34: 42/5_Kalman | C34: =IF(ISNUMBER(D34),SUM(INDIRECT(_xlfn.CONCAT("e",ROW(),":e",ROW()+D34-1))),"") | E34: =AND(AX34<$C$1,averaged_runs370!AQ34<$C$1,averaged_runs126!AQ34<$C$1)*1 | F34: =IF(TRUE,SQRT(averaged_runs126!AQ34^2/2+averaged_runs370!AQ34^2/2+AX34^2*0),"") | G34: =IF(E34,averaged_runs126!AQ34,"") | H34: =IF(E34,AX34,"") | I34: =IF(E34,averaged_runs370!AQ34,"") | J34: c | K34: 17.94 | L34: 77.72 | M34: 0.05206784 | N34: 55.214609 | O34: -0.80777778 | P34: -3.7520833 | Q34: -2.8662592 | R34: -1.365 | S34: -4.4116667 | T34: -1.17 | U34: -4.4116667 | V34: 4.4580357 | W34: 0.051085139 | X34: 0.0059784349 | Y34: 0.101291 | Z34: 0.05206784 | AA34: 24.607027 | AB34: -0.80611111 | AC34: -3.74875 | AD34: -3.1640476 | AE34: -1.3633333 | AF34: -4.4083333 | AG34: -0.995 | AH34: -4.2983333 | AI34: 3.2060714 | AJ34: 0.101291 | AK34: 5.018837 | AL34: 2.9941635 | AM34: 5.8874218 | AN34: 2.3857885 | AO34: 0.99396675 | AP34: 18.168 | AQ34: 18.868 | AR34: 0.012999521 | AS34: 0.032687816 | AT34: 6.84666 | AU34: 229.60632 | AV34: 0.073634719 | AW34: 0.085810585 | AX34: 0.095832495 | AY34: 0.095130394 | AZ34: 0.1041068
A35: removeGreensfx | B35: 42/6_Remove_IV | C35: =IF(ISNUMBER(D35),SUM(INDIRECT(_xlfn.CONCAT("e",ROW(),":e",ROW()+D35-1))),"") | D35: 4 | E35: =AND(AX35<$C$1,averaged_runs370!AQ35<$C$1,averaged_runs126!AQ35<$C$1)*1 | F35: =IF(TRUE,SQRT(averaged_runs126!AQ35^2/2+averaged_runs370!AQ35^2/2+AX35^2*0),"") | G35: =IF(TRUE,averaged_runs126!AQ35,"") | H35: =IF(TRUE,AX35,"") | I35: =IF(TRUE,averaged_runs370!AQ35,"") | J35: c | K35: 3.66 | L35: 38.08 | M35: -0.031400051 | N35: 109.02927 | O35: 2.4652778 | P35: 1.6673611 | Q35: 2.0102395 | R35: 1.175 | S35: -0.056666666 | T35: 3.66 | U35: 3.13 | V35: 2.6673106 | W35: 0.06 | X35: -0.021751757 | Y35: -0.025834234 | Z35: -0.031400051 | AA35: 87.048123 | AB35: 2.4669444 | AC35: 1.6706944 | AD35: 1.9327401 | AE35: 1.1766667 | AF35: -0.053333333 | AG35: 3.2166667 | AH35: 2.3216667 | AI35: 2.1340893 | AJ35: -0.025834234 | AK35: 3.892676 | AL35: 3.7623387 | AM35: 3.3858721 | AN35: 4.2625259 | AO35: 1.1220742 | AP35: 26.2 | AQ35: 26.98 | AR35: 0.091638763 | AS35: 0.19579522 | AT35: 14.40884 | AU35: 259.19913 | AV35: 0.074573895 | AW35: 0.070807542 | AX35: 0.070065136 | AY35: 0.082175883 | AZ35: 0.081319414
A36: removeMEI_cons | B36: 42/6_Remove_IV | C36: =IF(ISNUMBER(D36),SUM(INDIRECT(_xlfn.CONCAT("e",ROW(),":e",ROW()+D36-1))),"") | E36: =AND(AX36<$C$1,averaged_runs370!AQ36<$C$1,averaged_runs126!AQ36<$C$1)*1 | F36: =IF(TRUE,SQRT(averaged_runs126!AQ36^2/2+averaged_runs370!AQ36^2/2+AX36^2*0),"") | G36: =IF(E36,averaged_runs126!AQ36,"") | H36: =IF(E36,AX36,"") | I36: =IF(E36,averaged_runs370!AQ36,"") | J36: c | K36: 28.14 | L36: 61.82 | M36: -0.066640382 | N36: -93.61755 | O36: 3.0395278 | P36: 7.1086111 | Q36: 5.1789249 | R36: 1.1116667 | S36: 2.51 | T36: 4.73 | U36: 11.613333 | V36: 6.676237 | W36: 0.1000238 | X36: 0.0022780992 | Y36: -0.10943599 | Z36: -0.066640382 | AA36: -136.10587 | AB36: 3.0411944 | AC36: 7.1119444 | AD36: 5.4930289 | AE36: 1.1133333 | AF36: 2.5133333 | AG36: 4.6133333 | AH36: 11.496667 | AI36: 5.4930289 | AJ36: -0.10943599 | AK36: 3.1721936 | AL36: 2.1306413 | AM36: 3.5086656 | AN36: 2.0484503 | AO36: -0.2603379 | AP36: 34.398 | AQ36: 34.458 | AR36: 1.4746385e-08 | AS36: 4.1043699e-05 | AT36: 21.61248 | AU36: -60.138055 | AV36: 0.10148033 | AW36: 0.1060632 | AX36: 0.11511401 | AY36: 0.11345082 | AZ36: 0.1219156
A37: removeMEI_volc_cons | B37: 42/6_Remove_IV | C37: =IF(ISNUMBER(D37),SUM(INDIRECT(_xlfn.CONCAT("e",ROW(),":e",ROW()+D37-1))),"") | E37: =AND(AX37<$C$1,averaged_runs370!AQ37<$C$1,averaged_runs126!AQ37<$C$1)*1 | F37: =IF(TRUE,SQRT(averaged_runs126!AQ37^2/2+averaged_runs370!AQ37^2/2+AX37^2*0),"") | G37: =IF(E37,averaged_runs126!AQ37,"") | H37: =IF(E37,AX37,"") | I37: =IF(E37,averaged_runs370!AQ37,"") | J37: c | K37: 7.14 | L37: 42.06 | M37: -0.020347383 | N37: 88.517167 | O37: 0.33316667 | P37: 3.9596111 | Q37: 2.2854199 | R37: -1.7166667 | S37: -0.39333333 | T37: 0.33166667 | U37: 8.1133333 | V37: 4.5520544 | W37: 0.069852582 | X37: 0.0096958379 | Y37: -0.068796947 | Z37: -0.020347383 | AA37: 72.963078 | AB37: 0.33483333 | AC37: 3.9629444 | AD37: 2.4584242 | AE37: -1.715 | AF37: -0.39 | AG37: 0.63833333 | AH37: 7.4783333 | AI37: 2.6432195 | AJ37: -0.068796947 | AK37: 3.916701 | AL37: 3.5061094 | AM37: 4.3944129 | AN37: 3.412463 | AO37: 0.73993344 | AP37: 36.756 | AQ37: 37.176 | AR37: 0.060799369 | AS37: 0.14633068 | AT37: 22.52086 | AU37: 88.792012 | AV37: 0.0983527 | AW37: 0.085898916 | AX37: 0.086661544 | AY37: 0.094961028 | AZ37: 0.095692977
A38: removeMEI_volc_refit | B38: 42/6_Remove_IV | E38: =AND(AX38<$C$1,averaged_runs370!AQ38<$C$1,averaged_runs126!AQ38<$C$1)*1 | F38: =IF(TRUE,SQRT(averaged_runs126!AQ38^2/2+averaged_runs370!AQ38^2/2+AX38^2*0),"") | G38: =IF(E38,averaged_runs126!AQ38,"") | H38: =IF(E38,AX38,"") | I38: =IF(E38,averaged_runs370!AQ38,"") | J38: c | K38: 0.04 | L38: 15.08 | M38: -0.11188191 | N38: 44.287478 | O38: 5.0955833 | P38: 10.755917 | Q38: 8.261587 | R38: 3.0133333 | S38: 6 | T38: 7.2133333 | U38: 15.438333 | V38: 9.8989242 | W38: 0.13052266 | X38: -0.10351586 | Y38: -0.16041415 | Z38: -0.11188191 | AA38: 40.204539 | AB38: 5.09725 | AC38: 10.808139 | AD38: 8.7437809 | AE38: 3.015 | AF38: 6.0033333 | AG38: 7.05 | AH38: 15.556667 | AI38: 8.7437809 | AJ38: -0.16041415 | AK38: 1.8763474 | AL38: 1.6819282 | AM38: 2.0692914 | AN38: 1.6772018 | AO38: 0.50135554 | AP38: 34.426 | AQ38: 34.526 | AR38: 0.51790532 | AS38: 0.59915008 | AT38: 23.76224 | AU38: 51.639621 | AV38: 0.14250624 | AW38: 0.14268306 | AX38: 0.15827523 | AY38: 0.14807835 | AZ38: 0.16306542
A39: cons_hArrh_CO2forc | B39: 43/0_Linear | C39: =IF(ISNUMBER(D39),SUM(INDIRECT(_xlfn.CONCAT("e",ROW(),":e",ROW()+D39-1))),"") | D39: 2 | E39: =AND(AX39<$C$1,averaged_runs370!AQ39<$C$1,averaged_runs126!AQ39<$C$1)*1 | F39: =IF(TRUE,SQRT(averaged_runs126!AQ39^2/2+averaged_runs370!AQ39^2/2+AX39^2*0),"") | G39: =IF(E39,averaged_runs126!AQ39,"") | H39: =IF(E39,AX39,"") | I39: =IF(E39,averaged_runs370!AQ39,"") | J39: c | K39: 39.92 | L39: 49.8 | M39: 0.31393469 | N39: -35.288854 | O39: -7.3716667 | P39: -14.988333 | Q39: -7.4107051 | R39: -7.3716667 | S39: -14.988333 | T39: -7.3716667 | U39: -14.988333 | V39: 13.78562 | W39: 0.2681712 | X39: 0.15637928 | Y39: 0.5349787 | Z39: 0.31393469 | AA39: -34.861607 | AB39: -7.37 | AC39: -14.985 | AD39: -6.1908333 | AE39: -7.37 | AF39: -14.985 | AG39: -7.37 | AH39: -14.985 | AI39: 6.1908333 | AJ39: 0.5349787 | AK39: 0.75539741 | AL39: 0.47750876 | AM39: 0.76350067 | AN39: 0.4808212 | AO39: -2.2827874 | AP39: 12.42 | AQ39: 12.34 | AR39: 7.0205749e-07 | AS39: 0.00019380323 | AT39: 0.21714 | AU39: -527.32389 | AV39: 0.2512729 | AW39: 0.38717408 | AX39: 0.45251836 | AY39: 0.38514851 | AZ39: 0.45081768
A40: OLS_refit_CO2forc | B40: 43/0_Linear | C40: =IF(ISNUMBER(D40),SUM(INDIRECT(_xlfn.CONCAT("e",ROW(),":e",ROW()+D40-1))),"") | E40: =AND(AX40<$C$1,averaged_runs370!AQ40<$C$1,averaged_runs126!AQ40<$C$1)*1 | F40: =IF(TRUE,SQRT(averaged_runs126!AQ40^2/2+averaged_runs370!AQ40^2/2+AX40^2*0),"") | G40: =IF(E40,averaged_runs126!AQ40,"") | H40: =IF(E40,AX40,"") | I40: =IF(E40,averaged_runs370!AQ40,"") | J40: c | K40: 140.26 | L40: 186.98 | M40: 0.089251709 | N40: -601.31035 | O40: -4.4666667 | P40: -6.7333333 | Q40: -5.7153114 | R40: -4.4666667 | S40: -6.7333333 | T40: -4.4666667 | U40: -6.7333333 | V40: 6.7995493 | W40: 0.025732373 | X40: 0.039000297 | Y40: 0.14014378 | Z40: 0.089251709 | AA40: -680.72915 | AB40: -4.465 | AC40: -6.73 | AD40: -5.9865476 | AE40: -4.465 | AF40: -6.73 | AG40: -4.465 | AH40: -6.73 | AI40: 5.9865476 | AJ40: 0.14014378 | AK40: 1.4568751 | AL40: 0.56645971 | AM40: 0.8134525 | AN40: 0.081745906 | AO40: -4.7314454 | AP40: 13.58 | AQ40: 14 | AR40: 5.2280392e-11 | AS40: 7.8073248e-08 | AT40: 1.06578 | AU40: -1092.9639 | AV40: 0.089991123 | AW40: 0.11546121 | AX40: 0.1318727 | AY40: 0.12168644 | AZ40: 0.13603478
...

Sheet averaged_runs370
A1: method_name | B1: method_class | C1: c/r | D1: #q<0.1 | E1: #q<0.5 | F1: 100bias | G1: 100log-l | H1: Edyrs15 | I1: Edyrs20 | J1: EdyrsA | K1: Fdyrs15 | L1: Fdyrs20 | M1: Mdyrs15 | N1: Mdyrs20 | O1: RMSyrsA | P1: avg_unc.(1se) | Q1: bias | R1: bias50 | S1: e100bias | T1: e100log-l | U1: eEdyrs15 | V1: eEdyrs20 | W1: eEdyrsA | X1: eFdyrs15 | Y1: eFdyrs20 | Z1: eMdyrs15 | AA1: eMdyrs20 | AB1: eRMSyrsA | AC1: ebias50 | AD1: el15 | AE1: el20 | AF1: l15 | AG1: l20 | AH1: log-likeli | AI1: ncEdyrs | AJ1: nceEdyrs | AK1: q_min | AL1: q_small5 | AM1: smooth_r | AN1: tlog-l | AO1: RMS | AP1: 100RMS | AQ1: 75RMS | AR1: e100RMS | AS1: e75RMS
A2: lag10y | B2: 42/1_Run_Means | C2: c | D2: 98.02 | E2: 159.4 | F2: -0.1292201 | G2: -339.64771 | H2: 4.9341667 | I2: 4.6025 | J2: 4.6054809 | K2: 4.9133333 | L2: 4.5866667 | M2: 4.955 | N2: 4.6183333 | O2: 4.6948946 | P2: 0.041412014 | Q2: -0.066930097 | R2: -0.15777032 | S2: -0.1292201 | T2: -409.68211 | U2: 4.9458333 | V2: 4.5441667 | W2: 4.6027899 | X2: 4.925 | Y2: 4.5283333 | Z2: 4.9666667 | AA2: 4.56 | AB2: 4.6027899 | AC2: -0.15777032 | AD2: 1.131505 | AE2: 0.49149251 | AF2: 0.43687683 | AG2: 0.20302587 | AH2: -0.7404043 | AI2: 23.744 | AJ2: 23.324 | AK2: 4.1868138e-07 | AL2: 1.0929074e-05 | AM2: 2.89282 | AN2: -171.03339 | AO2: 0.096506215 | AP2: 0.13639421 | AQ2: 0.14951095 | AR2: 0.14415906 | AS2: 0.15625409
A3: lag5y | B3: 42/1_Run_Means | C3: c | D3: 36.22 | E3: 103.34 | F3: -0.057070717 | G3: -28.692183 | H3: 2.4 | I3: 1.98 | J3: 2.1076647 | K3: 1.9933333 | L3: 1.7766667 | M3: 2.8066667 | N3: 2.1833333 | O3: 2.4995804 | P3: 0.048642076 | Q3: -0.031939754 | R3: -0.071403538 | S3: -0.057070717 | T3: -100.87748 | U3: 2.4116667 | V3: 1.9216667 | W3: 2.1027174 | X3: 2.005 | Y3: 1.7183333 | Z3: 2.7516667 | AA3: 2.0666667 | AB3: 2.128442 | AC3: -0.071403538 | AD3: 4.5424821 | AE3: 4.308084 | AF3: 3.3072656 | AG3: 4.0589124 | AH3: 0.40406896 | AI3: 25.856 | AJ3: 25.376 | AK3: 1.5809028e-05 | AL3: 0.00064781027 | AM3: 5.64268 | AN3: 93.339929 | AO3: 0.07347753 | AP3: 0.079507493 | AQ3: 0.083538695 | AR3: 0.092304363 | AS3: 0.095458771
A4: offset11y | B4: 42/1_Run_Means | C4: c | D4: 85.34 | E4: 168.64 | F4: -0.033321102 | G4: 120.09039 | H4: 1.09 | I4: 1.54 | J4: 1.3514205 | K4: 1.09 | L4: 1.54 | M4: 1.09 | N4: 1.54 | O4: 1.8808493 | P4: 0.040544431 | Q4: 0.036251875 | R4: -0.064797985 | S4: -0.033321102 | T4: 53.507221 | U4: 1.1016667 | V4: 1.4816667 | W4: 1.3377174 | X4: 1.1016667 | Y4: 1.4816667 | Z4: 1.1016667 | AA4: 1.4816667 | AB4: 1.4272826 | AC4: -0.064797985 | AD4: 5.6144166 | AE4: 5.6439819 | AF4: 7.0788106 | AG4: 5.2614734 | AH4: -0.32436605 | AI4: 23.68 | AJ4: 23.26 | AK4: 2.2368432e-05 | AL4: 6.6927709e-05 | AM4: 2.64078 | AN4: -74.928557 | AO4: 0.082720964 | AP4: 0.055904925 | AQ4: 0.061676945 | AR4: 0.072136809 | AS4: 0.075929309
A5: raw1y | B5: 42/1_Run_Means | C5: c | D5: 0.04 | E5: 0.76 | F5: -0.00048493387 | G5: 67.66028 | H5: -0.048333333 | I5: 0.14347222 | J5: -0.18026386 | K5: -3.6266667 | L5: -2.7866667 | M5: -0.665 | N5: -0.04 | O5: 1.6721078 | P5: 0.12690076 | Q5: -0.0031054247 | R5: -0.0025897962 | S5: -0.00048493387 | T5: 60.420953 | U5: -0.036666667 | V5: 0.085138889 | W5: -0.18970756 | X5: -3.615 | Y5: -2.845 | Z5: -0.78666667 | AA5: 0.32333333 | AB5: 0.96170066 | AC5: -0.0025897962 | AD5: 2.2908649 | AE5: 2.2985053 | AF5: 2.3549582 | AG5: 2.3910461 | AH5: 0.70694929 | AI5: 54.012 | AJ5: 53.072 | AK5: 0.62199401 | AL5: 0.86912427 | AM5: 29.10296 | AN5: 163.30529 | AO5: 0.11831905 | AP5: 0.11512984 | AQ5: 0.11261443 | AR5: 0.12429362 | AS5: 0.1219778
A6: Bayes_seq_CP | B6: 42/2_LT_Fits | C6: c | D6: 90.94 | E6: 140.84 | F6: -0.072335721 | G6: -140.99685 | H6: 2.6583333 | I6: 3.5 | J6: 2.5709044 | K6: 2.6583333 | L6: 3.5 | M6: 2.6583333 | N6: 3.5 | O6: 2.9220993 | P6: 0.033011747 | Q6: -0.054947056 | R6: -0.096612466 | S6: -0.072335721 | T6: -231.27713 | U6: 2.67 | V6: 3.4416667 | W6: 2.5767029 | X6: 2.67 | Y6: 3.4416667 | Z6: 2.67 | AA6: 3.4416667 | AB6: 2.5767029 | AC6: -0.096612466 | AD6: 4.1178223 | AE6: 1.3869555 | AF6: 3.2099196 | AG6: 0.93712382 | AH6: -1.5429735 | AI6: 23.52 | AJ6: 23.08 | AK6: 3.7642282e-08 | AL6: 2.3352329e-07 | AM6: 2.35552 | AN6: -296.25092 | AO6: 0.083193039 | AP6: 0.089562242 | AQ6: 0.098363558 | AR6: 0.099864363 | AS6: 0.10618095
A7: butterworth | B7: 42/2_LT_Fits | C7: c | D7: 0.72 | E7: 1.28 | F7: -0.043317748 | G7: 46.704702 | H7: 2.0344444 | I7: 1.4680556 | J7: 1.5501525 | K7: 1.1566667 | L7: 0.54833333 | M7: 2.7733333 | N7: 2.1533333 | O7: 1.980269 | P7: 0.194984 | Q7: -0.038560249 | R7: -0.050466357 | S7: -0.043317748 | T7: 42.011071 | U7: 2.0461111 | V7: 1.4097222 | W7: 1.54875 | X7: 1.1683333 | Y7: 0.49 | Z7: 1.875 | AA7: 2.0583333 | AB7: 1.6025664 | AC7: -0.050466357 | AD7: 1.9345013 | AE7: 1.547785 | AF7: 1.9486168 | AG7: 1.5911151 | AH7: 0.63423461 | AI7: 35.2 | AJ7: 34.44 | AK7: 0.37902689 | AL7: 0.97307416 | AM7: 12.2893 | AN7: 90.061315 | AO7: 0.075267833 | AP7: 0.076791898 | AQ7: 0.08049352 | AR7: 0.091288431 | AS7: 0.09457882
A8: hinge75meet | B8: 42/2_LT_Fits | C8: c | D8: 50.5 | E8: 75.12 | F8: -0.1261985 | G8: -243.24351 | H8: 1.9666667 | I8: 5.0833333 | J8: 5.6302168 | K8: 1.9666667 | L8: 5.0833333 | M8: 1.9666667 | N8: 5.0833333 | O8: 6.7651579 | P8: 0.064634548 | Q8: -0.072331031 | R8: -0.24345628 | S8: -0.1261985 | T8: -261.3514 | U8: 1.9783333 | V8: 5.025 | W8: 5.4644928 | X8: 1.9783333 | Y8: 5.025 | Z8: 1.9783333 | AA8: 5.025 | AB8: 5.4644928 | AC8: -0.24345628 | AD8: 4.1869967 | AE8: 0.99324471 | AF8: 4.4721799 | AG8: 0.7057741 | AH8: -1.0746008 | AI8: 23.28 | AJ8: 22.98 | AK8: 3.1612444e-05 | AL8: 3.9018295e-05 | AM8: 1.70664 | AN8: -167.63772 | AO8: 0.13975029 | AP8: 0.17581577 | AQ8: 0.20491041 | AR8: 0.17966188 | AS8: 0.20711418
