Workbook

Sheet meiv2
A1: YEAR | B1: DJ | C1: JF | D1: FM | E1: MA | F1: AM | G1: MJ | H1: JJ | I1: JA | J1: AS | K1: SO | L1: ON | M1: ND | N1: Avg
A2: 1979 | B2: 0.47 | C2: 0.29 | D2: -0.05 | E2: 0.21 | F2: 0.27 | G2: -0.11 | H2: -0.11 | I2: 0.47 | J2: 0.38 | K2: 0.23 | L2: 0.53 | M2: 0.63 | N2: =AVERAGE(B2:M2) -> 0.2675 | Q2: m1 | U2: b
A3: 1980 | B3: 0.33 | C3: 0.2 | D3: 0.39 | E3: 0.51 | F3: 0.45 | G3: 0.55 | H3: 0.47 | I3: 0.03 | J3: 0.12 | K3: 0.02 | L3: -0.07 | M3: -0.12 | N3: =AVERAGE(B3:M3) -> 0.24 | P3: AS | Q3: {=LINEST(J2:J46,F2:I46,TRUE,TRUE)} -> 1.1426009 | R3: -0.34182679 | S3: 0.28656523 | T3: -0.092474448 | U3: -0.012985415
A4: 1981 | B4: -0.36 | C4: -0.23 | D4: 0.33 | E4: 0.43 | F4: -0.24 | G4: -0.7 | H4: -0.61 | I4: -0.34 | J4: -0.07 | K4: -0.16 | L4: -0.27 | M4: -0.19 | N4: =AVERAGE(B4:M4) -> -0.20083333 | Q4: 0.1077058 | R4: 0.14978881 | S4: 0.14030675 | T4: 0.0871368 | U4: 0.030430982
A5: 1982 | B5: -0.43 | C5: -0.49 | D5: -0.27 | E5: -0.36 | F5: -0.12 | G5: 0.62 | H5: 1.65 | I5: 1.91 | J5: 1.69 | K5: 1.78 | L5: 2.14 | M5: 2.37 | N5: =AVERAGE(B5:M5) -> 0.87416667 | Q5: 0.96322646 | R5: 0.20256184 | S5: #N/A | T5: #N/A | U5: #N/A
A6: 1983 | B6: 2.48 | C6: 2.68 | D6: 2.61 | E6: 2.76 | F6: 2.86 | G6: 1.98 | H6: 0.63 | I6: -0.17 | J6: -0.49 | K6: -0.53 | L6: -0.47 | M6: -0.5 | N6: =AVERAGE(B6:M6) -> 1.1533333 | Q6: 261.93463 | R6: 40 | S6: #N/A | T6: #N/A | U6: #N/A
A7: 1984 | B7: -0.54 | C7: -0.56 | D7: -0.16 | E7: 0.07 | F7: -0.45 | G7: -0.66 | H7: -0.34 | I7: -0.2 | J7: -0.14 | K7: -0.19 | L7: -0.58 | M7: -0.28 | N7: =AVERAGE(B7:M7) -> -0.33583333 | Q7: 42.990073 | R7: 1.6412519 | S7: #N/A | T7: #N/A | U7: #N/A
A8: 1985 | B8: -0.25 | C8: -0.58 | D8: -0.6 | E8: -0.76 | F8: -1.23 | G8: -0.67 | H8: -0.1 | I8: -0.49 | J8: -0.56 | K8: -0.08 | L8: -0.06 | M8: -0.42 | N8: =AVERAGE(B8:M8) -> -0.48333333 | Q8: =Q7/(Q7+R7) -> 0.96322646
A9: 1986 | B9: -0.4 | C9: -0.34 | D9: -0.4 | E9: -0.53 | F9: -0.26 | G9: 0.01 | H9: 0.41 | I9: 0.97 | J9: 1.29 | K9: 0.56 | L9: 0.64 | M9: 1.06 | N9: =AVERAGE(B9:M9) -> 0.25083333
A10: 1987 | B10: 1.03 | C10: 1.16 | D10: 1.57 | E10: 1.74 | F10: 1.96 | G10: 2.07 | H10: 1.88 | I10: 1.46 | J10: 1.26 | K10: 1.18 | L10: 0.9 | M10: 0.79 | N10: =AVERAGE(B10:M10) -> 1.4166667
A11: 1988 | B11: 0.63 | C11: 0.33 | D11: 0.17 | E11: -0.01 | F11: -0.39 | G11: -1.17 | H11: -1.78 | I11: -1.81 | J11: -1.8 | K11: -1.59 | L11: -1.7 | M11: -1.55 | N11: =AVERAGE(B11:M11) -> -0.88916667
A12: 1989 | B12: -1.12 | C12: -1.1 | D12: -1.24 | E12: -1.09 | F12: -1.03 | G12: -0.99 | H12: -1.08 | I12: -0.66 | J12: -0.53 | K12: -0.49 | L12: -0.36 | M12: -0.07 | N12: =AVERAGE(B12:M12) -> -0.81333333
A13: 1990 | B13: 0.13 | C13: 0.45 | D13: 0.61 | E13: 0.17 | F13: 0.08 | G13: 0.05 | H13: 0.13 | I13: 0.02 | J13: 0.22 | K13: -0.07 | L13: 0.12 | M13: 0.31 | N13: =AVERAGE(B13:M13) -> 0.185 | P13: SO | Q13: {=LINEST(K2:K46,F2:I46,TRUE,TRUE)} -> 0.75412543 | R13: 0.068830156 | S13: 0.24512182 | T13: -0.1240023 | U13: -0.013187572
A14: 1991 | B14: 0.19 | C14: 0.08 | D14: 0.2 | E14: 0.2 | F14: 0.35 | G14: 0.97 | H14: 0.91 | I14: 0.37 | J14: 0.54 | K14: 0.97 | L14: 1.04 | M14: 1.23 | N14: =AVERAGE(B14:M14) -> 0.5875 | Q14: 0.16791996 | R14: 0.23352995 | S14: 0.21874683 | T14: 0.13585162 | U14: 0.047443769
A15: 1992 | B15: 1.68 | C15: 1.58 | D15: 1.71 | E15: 1.97 | F15: 1.68 | G15: 1.51 | H15: 0.62 | I15: -0.02 | J15: 0.4 | K15: 0.67 | L15: 0.62 | M15: 0.73 | N15: =AVERAGE(B15:M15) -> 1.0958333 | Q15: 0.91056982 | R15: 0.31580635 | S15: #N/A | T15: #N/A | U15: #N/A
A16: 1993 | B16: 0.79 | C16: 0.89 | D16: 0.77 | E16: 0.98 | F16: 1.47 | G16: 1.51 | H16: 0.9 | I16: 0.6 | J16: 0.61 | K16: 0.96 | L16: 0.7 | M16: 0.27 | N16: =AVERAGE(B16:M16) -> 0.87083333 | Q16: 101.81908 | R16: 40 | S16: #N/A | T16: #N/A | U16: #N/A
A17: 1994 | B17: -0.01 | C17: -0.21 | D17: -0.23 | E17: 0.01 | F17: -0.03 | G17: 0.25 | H17: 0.96 | I17: 0.87 | J17: 1.1 | K17: 1.52 | L17: 1.01 | M17: 0.91 | N17: =AVERAGE(B17:M17) -> 0.5125 | Q17: 40.619152 | R17: 3.9893459 | S17: #N/A | T17: #N/A | U17: #N/A
A18: 1995 | B18: 0.82 | C18: 0.54 | D18: 0.17 | E18: 0.13 | F18: 0.14 | G18: 0.01 | H18: -0.29 | I18: -0.7 | J18: -0.94 | K18: -0.74 | L18: -0.77 | M18: -0.9 | N18: =AVERAGE(B18:M18) -> -0.21083333 | Q18: =Q17/(Q17+R17) -> 0.91056982
A19: 1996 | B19: -0.85 | C19: -0.8 | D19: -0.66 | E19: -0.76 | F19: -0.85 | G19: -0.91 | H19: -0.83 | I19: -0.64 | J19: -0.31 | K19: -0.37 | L19: -0.34 | M19: -0.47 | N19: =AVERAGE(B19:M19) -> -0.64916667
A20: 1997 | B20: -0.65 | C20: -0.72 | D20: -0.3 | E20: 0.15 | F20: 0.71 | G20: 2.34 | H20: 2.26 | I20: 2.26 | J20: 2.2 | K20: 2.06 | L20: 2.14 | M20: 2.11 | N20: =AVERAGE(B20:M20) -> 1.2133333
A21: 1998 | B21: 2.3 | C21: 2.45 | D21: 2.27 | E21: 2.61 | F21: 2.33 | G21: 0.42 | H21: -1.53 | I21: -1.82 | J21: -1.4 | K21: -1.29 | L21: -1.34 | M21: -1.29 | N21: =AVERAGE(B21:M21) -> 0.30916667
A22: 1999 | B22: -1.28 | C22: -1.2 | D22: -1.15 | E22: -1.16 | F22: -1.33 | G22: -1.26 | H22: -1.18 | I22: -1.03 | J22: -1.16 | K22: -1.33 | L22: -1.33 | M22: -1.43 | N22: =AVERAGE(B22:M22) -> -1.2366667
A23: 2000 | B23: -1.25 | C23: -1.26 | D23: -1.37 | E23: -0.9 | F23: -0.93 | G23: -1.18 | H23: -0.61 | I23: -0.08 | J23: -0.35 | K23: -0.52 | L23: -0.86 | M23: -0.79 | N23: =AVERAGE(B23:M23) -> -0.84166667 | P23: ON | Q23: {=LINEST(L2:L46,F2:I46,TRUE,TRUE)} -> 0.76285773 | R23: -0.009486534 | S23: 0.38155184 | T23: -0.24507827 | U23: 0.010176652
A24: 2001 | B24: -0.83 | C24: -0.86 | D24: -0.78 | E24: -0.55 | F24: -0.51 | G24: -0.73 | H24: 0.04 | I24: 0.38 | J24: -0.06 | K24: -0.22 | L24: -0.28 | M24: 0.06 | N24: =AVERAGE(B24:M24) -> -0.36166667 | Q24: 0.17829894 | R24: 0.24796421 | S24: 0.23226736 | T24: 0.14424848 | U24: 0.050376223
A25: 2002 | B25: 0.09 | C25: -0.26 | D25: -0.2 | E25: -0.36 | F25: -0.14 | G25: 0.34 | H25: 0.44 | I25: 1.01 | J25: 0.88 | K25: 0.84 | L25: 0.84 | M25: 0.91 | N25: =AVERAGE(B25:M25) -> 0.36583333 | Q25: 0.89956928 | R25: 0.33532603 | S25: #N/A | T25: #N/A | U25: #N/A
A26: 2003 | B26: 0.82 | C26: 0.63 | D26: 0.53 | E26: -0.11 | F26: -0.61 | G26: -0.1 | H26: 0.01 | I26: 0.05 | J26: 0.18 | K26: 0.28 | L26: 0.3 | M26: 0.14 | N26: =AVERAGE(B26:M26) -> 0.17666667 | Q26: 89.571129 | R26: 40 | S26: #N/A | T26: #N/A | U26: #N/A
A27: 2004 | B27: 0.19 | C27: -0.05 | D27: -0.43 | E27: -0.23 | F27: -0.46 | G27: -0.39 | H27: 0.46 | I27: 0.77 | J27: 0.59 | K27: 0.4 | L27: 0.56 | M27: 0.48 | N27: =AVERAGE(B27:M27) -> 0.1575 | Q27: 40.286782 | R27: 4.497742 | S27: #N/A | T27: #N/A | U27: #N/A
A28: 2005 | B28: 0.09 | C28: 0.61 | D28: 0.83 | E28: 0.14 | F28: 0.19 | G28: 0.2 | H28: 0 | I28: 0.01 | J28: -0.02 | K28: -0.66 | L28: -0.7 | M28: -0.7 | N28: =AVERAGE(B28:M28) -> -0.00083333333 | Q28: =Q27/(Q27+R27) -> 0.89956928
A29: 2006 | B29: -0.64 | C29: -0.48 | D29: -0.62 | E29: -0.84 | F29: -0.42 | G29: -0.18 | H29: 0.21 | I29: 0.59 | J29: 0.65 | K29: 0.77 | L29: 1 | M29: 0.64 | N29: =AVERAGE(B29:M29) -> 0.056666667
A30: 2007 | B30: 0.64 | C30: 0.39 | D30: -0.19 | E30: -0.32 | F30: -0.41 | G30: -0.83 | H30: -0.75 | I30: -0.9 | J30: -1.06 | K30: -1.13 | L30: -1.12 | M30: -1.19 | N30: =AVERAGE(B30:M30) -> -0.5725
A31: 2008 | B31: -1.06 | C31: -1.27 | D31: -1.52 | E31: -1.11 | F31: -0.99 | G31: -0.8 | H31: -0.78 | I31: -1.01 | J31: -1.02 | K31: -1.08 | L31: -0.98 | M31: -1.01 | N31: =AVERAGE(B31:M31) -> -1.0525
A32: 2009 | B32: -1.01 | C32: -0.85 | D32: -0.95 | E32: -0.81 | F32: -0.72 | G32: -0.05 | H32: 0.56 | I32: 0.56 | J32: 0.42 | K32: 0.56 | L32: 1.04 | M32: 0.95 | N32: =AVERAGE(B32:M32) -> -0.025
A33: 2010 | B33: 0.93 | C33: 1.28 | D33: 1.33 | E33: 0.49 | F33: -0.12 | G33: -1.29 | H33: -2.43 | I33: -2.38 | J33: -2.26 | K33: -2.16 | L33: -2.01 | M33: -1.86 | N33: =AVERAGE(B33:M33) -> -0.87333333 | P33: ND | Q33: {=LINEST(M2:M46,F2:I46,TRUE,TRUE)} -> 0.94726765 | R33: -0.22602306 | S33: 0.38040417 | T33: -0.20928658 | U33: 0.018378643
A34: 2011 | B34: -1.77 | C34: -1.59 | D34: -1.75 | E34: -1.69 | F34: -1.23 | G34: -1.02 | H34: -0.75 | I34: -0.81 | J34: -1.08 | K34: -1.3 | L34: -1.14 | M34: -1.18 | N34: =AVERAGE(B34:M34) -> -1.2758333 | Q34: 0.19523918 | R34: 0.27152338 | S34: 0.25433517 | T34: 0.15795358 | U34: 0.055162485
A35: 2012 | B35: -1.07 | C35: -0.68 | D35: -0.58 | E35: -0.38 | F35: -0.32 | G35: -0.28 | H35: 0.34 | I35: -0.02 | J35: -0.29 | K35: -0.19 | L35: -0.03 | M35: -0.03 | N35: =AVERAGE(B35:M35) -> -0.29416667 | Q35: 0.87790293 | R35: 0.36718547 | S35: #N/A | T35: #N/A | U35: #N/A
A36: 2013 | B36: -0.06 | C36: -0.08 | D36: -0.12 | E36: -0.35 | F36: -0.68 | G36: -1.14 | H36: -0.79 | I36: -0.45 | J36: -0.33 | K36: -0.13 | L36: -0.16 | M36: -0.34 | N36: =AVERAGE(B36:M36) -> -0.38583333 | Q36: 71.902048 | R36: 40 | S36: #N/A | T36: #N/A | U36: #N/A
A37: 2014 | B37: -0.5 | C37: -0.42 | D37: -0.05 | E37: -0.16 | F37: -0.17 | G37: 0 | H37: 0.42 | I37: 0.23 | J37: -0.09 | K37: 0.12 | L37: 0.37 | M37: 0.35 | N37: =AVERAGE(B37:M37) -> 0.0083333333 | Q37: 38.776824 | R37: 5.3930069 | S37: #N/A | T37: #N/A | U37: #N/A
A38: 2015 | B38: 0.23 | C38: 0.06 | D38: 0.15 | E38: 0.31 | F38: 0.95 | G38: 1.9 | H38: 1.79 | I38: 1.95 | J38: 2.24 | K38: 2.15 | L38: 1.94 | M38: 1.93 | N38: =AVERAGE(B38:M38) -> 1.3 | Q38: =Q37/(Q37+R37) -> 0.87790293
A39: 2016 | B39: 1.94 | C39: 1.81 | D39: 1.32 | E39: 1.33 | F39: 1.24 | G39: 0.36 | H39: -0.53 | I39: -0.27 | J39: -0.29 | K39: -0.54 | L39: -0.48 | M39: -0.37 | N39: =AVERAGE(B39:M39) -> 0.46
A40: 2017 | B40: -0.43 | C40: -0.42 | D40: -0.58 | E40: -0.19 | F40: 0.19 | G40: -0.24 | H40: -0.63 | I40: -0.73 | J40: -0.74 | K40: -0.59 | L40: -0.62 | M40: -0.74 | N40: =AVERAGE(B40:M40) -> -0.47666667
...

Sheet meiEXT
A1: YEAR | B1: DECJAN | C1: JANFEB | D1: FEBMAR | E1: MARAPR | F1: APRMAY | G1: MAYJUN | H1: JUNJUL | I1: JULAUG | J1: AUGSEP | K1: SEPOCT | L1: OCTNOV | M1: NOVDEC | N1: AVG
A2: 1871 | B2: 0.032 | C2: -0.055 | D2: 0.005 | E2: 0.42 | F2: 0.195 | G2: -0.639 | H2: -0.842 | I2: -0.474 | J2: -0.143 | K2: 0.072 | L2: 0.107 | M2: -0.206 | N2: =AVERAGE(B2:M2) -> -0.12733333
A3: 1872 | B3: -0.633 | C3: -0.875 | D3: -0.864 | E3: -0.664 | F3: -0.59 | G3: -0.618 | H3: -0.658 | I3: -0.795 | J3: -0.8 | K3: -0.669 | L3: -0.651 | M3: -0.847 | N3: =AVERAGE(B3:M3) -> -0.722
A4: 1873 | B4: -0.93 | C4: -0.991 | D4: -1.301 | E4: -1.489 | F4: -1.066 | G4: -0.689 | H4: -0.657 | I4: -0.646 | J4: -0.318 | K4: -0.012 | L4: -0.355 | M4: -0.54 | N4: =AVERAGE(B4:M4) -> -0.7495
A5: 1874 | B5: -0.611 | C5: -0.802 | D5: -1.036 | E5: -1.275 | F5: -1.258 | G5: -0.964 | H5: -0.902 | I5: -1.143 | J5: -1.148 | K5: -1.003 | L5: -0.771 | M5: -0.679 | N5: =AVERAGE(B5:M5) -> -0.966
A6: 1875 | B6: -0.774 | C6: -0.686 | D6: -0.67 | E6: -0.958 | F6: -1.315 | G6: -1.812 | H6: -1.964 | I6: -1.553 | J6: -1.295 | K6: -0.993 | L6: -0.682 | M6: -0.688 | N6: =AVERAGE(B6:M6) -> -1.1158333
A7: 1876 | B7: -0.878 | C7: -1.196 | D7: -1.504 | E7: -1.691 | F7: -1.878 | G7: -1.845 | H7: -1.435 | I7: -0.867 | J7: -0.393 | K7: -0.071 | L7: 0.088 | M7: 0.17 | N7: =AVERAGE(B7:M7) -> -0.95833333
A8: 1877 | B8: 0.193 | C8: 0.334 | D8: 0.373 | E8: 0.353 | F8: 0.441 | G8: 0.69 | H8: 1.318 | I8: 1.687 | J8: 1.788 | K8: 2.07 | L8: 2.165 | M8: 1.763 | N8: =AVERAGE(B8:M8) -> 1.0979167
A9: 1878 | B9: 1.877 | C9: 2.361 | D9: 2.495 | E9: 1.883 | F9: 1.006 | G9: 0.58 | H9: 0.54 | I9: 0.235 | J9: -0.371 | K9: -0.845 | L9: -0.911 | M9: -0.921 | N9: =AVERAGE(B9:M9) -> 0.66075
A10: 1879 | B10: -1.005 | C10: -0.729 | D10: -0.445 | E10: -0.447 | F10: -0.956 | G10: -1.18 | H10: -0.827 | I10: -0.607 | J10: -0.523 | K10: -0.557 | L10: -0.72 | M10: -1.031 | N10: =AVERAGE(B10:M10) -> -0.75225
A11: 1880 | B11: -1.057 | C11: -0.83 | D11: -0.899 | E11: -1.069 | F11: -0.965 | G11: -0.595 | H11: 0.113 | I11: 0.394 | J11: 0.083 | K11: -0.228 | L11: -0.128 | M11: 0.17 | N11: =AVERAGE(B11:M11) -> -0.41758333
A12: 1881 | B12: 0.148 | C12: 0.215 | D12: 0.174 | E12: 0.082 | F12: -0.105 | G12: -0.062 | H12: -0.153 | I12: -0.559 | J12: -0.656 | K12: -0.389 | L12: -0.499 | M12: -0.776 | N12: =AVERAGE(B12:M12) -> -0.215
A13: 1882 | B13: -0.598 | C13: -0.461 | D13: -0.585 | E13: -0.799 | F13: -1.028 | G13: -0.97 | H13: -0.686 | I13: -0.436 | J13: -0.267 | K13: -0.261 | L13: -0.379 | M13: -0.404 | N13: =AVERAGE(B13:M13) -> -0.57283333
... A109: 1978 | B109: 0.939 | C109: 0.846 | D109: 0.895 | E109: 0.57 | F109: 0.023 | G109: -0.235 | H109: -0.137 | I109: 0.19 | J109: -0.056 | K109: -0.142 | L109: 0.39 | M109: 0.626 | N109: =AVERAGE(B109:M109) -> 0.32575
A110: 1979 | B110: 0.577 | C110: 0.402 | D110: 0.132 | E110: 0.164 | F110: 0.623 | G110: 0.637 | H110: 0.346 | I110: 0.584 | J110: 0.876 | K110: 0.818 | L110: 0.831 | M110: 1.012 | N110: =AVERAGE(B110:M110) -> 0.5835 | O110: =AVERAGE(C110:N110) -> 0.58404167 | P110: strongly correlated!
A111: 1980 | B111: 1.014 | C111: 0.813 | D111: 0.832 | E111: 1.167 | F111: 1.249 | G111: 0.919 | H111: 0.783 | I111: 0.689 | J111: 0.411 | K111: 0.336 | L111: 0.226 | M111: 0.189 | N111: =AVERAGE(B111:M111) -> 0.719 | O111: =AVERAGE(C111:N111) -> 0.69441667
A112: 1981 | B112: -0.087 | C112: -0.337 | D112: -0.128 | E112: 0.362 | F112: 0.29 | G112: 0.013 | H112: -0.096 | I112: -0.076 | J112: 0.082 | K112: 0.201 | L112: 0.177 | M112: 0.064 | N112: =AVERAGE(B112:M112) -> 0.03875 | O112: =AVERAGE(C112:N112) -> 0.049229167
A113: 1982 | B113: 0.077 | C113: 0.019 | D113: 0.107 | E113: 0.44 | F113: 0.949 | G113: 1.48 | H113: 1.768 | I113: 1.841 | J113: 1.871 | K113: 2.254 | L113: 2.593 | M113: 2.777 | N113: =AVERAGE(B113:M113) -> 1.348 | O113: =AVERAGE(C113:N113) -> 1.4539167
A114: 1983 | B114: 3.08 | C114: 3.31 | D114: 3.349 | E114: 3.084 | F114: 2.665 | G114: 2.337 | H114: 1.922 | I114: 1.155 | J114: 0.462 | K114: 0.105 | L114: -0.099 | M114: 0.054 | N114: =AVERAGE(B114:M114) -> 1.7853333 | O114: =AVERAGE(C114:N114) -> 1.6774444
A115: 1984 | B115: 0.054 | C115: -0.166 | D115: -0.192 | E115: 0.096 | F115: -0.052 | G115: -0.402 | H115: -0.416 | I115: -0.365 | J115: -0.214 | K115: -0.102 | L115: -0.359 | M115: -0.66 | N115: =AVERAGE(B115:M115) -> -0.2315 | O115: =AVERAGE(C115:N115) -> -0.25529167
A116: 1985 | B116: -0.744 | C116: -0.777 | D116: -0.863 | E116: -0.772 | F116: -0.791 | G116: -0.533 | H116: -0.102 | I116: -0.365 | J116: -0.601 | K116: -0.257 | L116: 0.015 | M116: -0.151 | N116: =AVERAGE(B116:M116) -> -0.49508333 | O116: =AVERAGE(C116:N116) -> -0.47434028
A117: 1986 | B117: -0.278 | C117: -0.228 | D117: -0.087 | E117: -0.004 | F117: 0.141 | G117: 0.319 | H117: 0.377 | I117: 0.736 | J117: 1.147 | K117: 1.198 | L117: 1.237 | M117: 1.342 | N117: =AVERAGE(B117:M117) -> 0.49166667 | O117: =AVERAGE(C117:N117) -> 0.55580556
A118: 1987 | B118: 1.38 | C118: 1.529 | D118: 1.883 | E118: 2.171 | F118: 2.162 | G118: 2.069 | H118: 2.2 | I118: 2.343 | J118: 2.054 | K118: 1.824 | L118: 1.575 | M118: 1.49 | N118: =AVERAGE(B118:M118) -> 1.89 | O118: =AVERAGE(C118:N118) -> 1.9325
A119: 1988 | B119: 1.387 | C119: 1.02 | D119: 0.703 | E119: 0.429 | F119: -0.047 | G119: -0.735 | H119: -1.416 | I119: -1.704 | J119: -1.783 | K119: -1.76 | L119: -1.778 | M119: -1.67 | N119: =AVERAGE(B119:M119) -> -0.61283333 | O119: =AVERAGE(C119:N119) -> -0.77948611
A120: 1989 | B120: -1.468 | C120: -1.33 | D120: -1.198 | E120: -1.143 | F120: -1.124 | G120: -1.027 | H120: -0.951 | I120: -0.637 | J120: -0.35 | K120: -0.389 | L120: -0.33 | M120: 0.001 | N120: =AVERAGE(B120:M120) -> -0.82883333 | O120: =AVERAGE(C120:N120) -> -0.77556944
A121: 1990 | B121: 0.225 | C121: 0.462 | D121: 0.742 | E121: 0.723 | F121: 0.531 | G121: 0.422 | H121: 0.352 | I121: 0.147 | J121: 0.257 | K121: 0.454 | L121: 0.382 | M121: 0.298 | N121: =AVERAGE(B121:M121) -> 0.41625 | O121: =AVERAGE(C121:N121) -> 0.4321875
A122: 1991 | B122: 0.407 | C122: 0.413 | D122: 0.493 | E122: 0.763 | F122: 1.014 | G122: 1.184 | H122: 1.102 | I122: 0.553 | J122: 0.296 | K122: 0.8 | L122: 1.257 | M122: 1.45 | N122: =AVERAGE(B122:M122) -> 0.811 | O122: =AVERAGE(C122:N122) -> 0.84466667
... A136: 2005 | B136: 0.432 | C136: 0.28 | D136: 0.631 | E136: 0.773 | F136: 0.588 | G136: 0.737 | H136: 0.8 | I136: 0.492 | J136: 0.08 | K136: -0.661 | L136: -0.998 | M136: -0.954 | N136: =AVERAGE(B136:M136) -> 0.18333333 | O136: =AVERAGE(C136:N136) -> 0.16261111

Sheet mei_shift
A1: YEAR | B1: DECJAN | C1: JANFEB | D1: FEBMAR | E1: MARAPR | F1: APRMAY | G1: MAYJUN | H1: JUNJUL | I1: JULAUG | J1: AUGSEP | K1: SEPOCT | L1: OCTNOV | M1: NOVDEC | N1: AVG
A2: 1871 | B2: 0.032 | C2: -0.055 | D2: 0.005 | E2: 0.42 | F2: 0.195 | G2: -0.639 | H2: -0.842 | I2: -0.474 | J2: -0.143 | K2: 0.072 | L2: 0.107 | M2: -0.206
A3: 1872 | B3: -0.633 | C3: -0.875 | D3: -0.864 | E3: -0.664 | F3: -0.59 | G3: -0.618 | H3: -0.658 | I3: -0.795 | J3: -0.8 | K3: -0.669 | L3: -0.651 | M3: -0.847 | N3: =(SUM(B3:I3)+SUM(J2:M2))/12 -> -0.48891667
A4: 1873 | B4: -0.93 | C4: -0.991 | D4: -1.301 | E4: -1.489 | F4: -1.066 | G4: -0.689 | H4: -0.657 | I4: -0.646 | J4: -0.318 | K4: -0.012 | L4: -0.355 | M4: -0.54 | N4: =(SUM(B4:I4)+SUM(J3:M3))/12 -> -0.89466667
A5: 1874 | B5: -0.611 | C5: -0.802 | D5: -1.036 | E5: -1.275 | F5: -1.258 | G5: -0.964 | H5: -0.902 | I5: -1.143 | J5: -1.148 | K5: -1.003 | L5: -0.771 | M5: -0.679 | N5: =(SUM(B5:I5)+SUM(J4:M4))/12 -> -0.768
A6: 1875 | B6: -0.774 | C6: -0.686 | D6: -0.67 | E6: -0.958 | F6: -1.315 | G6: -1.812 | H6: -1.964 | I6: -1.553 | J6: -1.295 | K6: -0.993 | L6: -0.682 | M6: -0.688 | N6: =(SUM(B6:I6)+SUM(J5:M5))/12 -> -1.1110833
A7: 1876 | B7: -0.878 | C7: -1.196 | D7: -1.504 | E7: -1.691 | F7: -1.878 | G7: -1.845 | H7: -1.435 | I7: -0.867 | J7: -0.393 | K7: -0.071 | L7: 0.088 | M7: 0.17 | N7: =(SUM(B7:I7)+SUM(J6:M6))/12 -> -1.246
A8: 1877 | B8: 0.193 | C8: 0.334 | D8: 0.373 | E8: 0.353 | F8: 0.441 | G8: 0.69 | H8: 1.318 | I8: 1.687 | J8: 1.788 | K8: 2.07 | L8: 2.165 | M8: 1.763 | N8: =(SUM(B8:I8)+SUM(J7:M7))/12 -> 0.43191667
A9: 1878 | B9: 1.877 | C9: 2.361 | D9: 2.495 | E9: 1.883 | F9: 1.006 | G9: 0.58 | H9: 0.54 | I9: 0.235 | J9: -0.371 | K9: -0.845 | L9: -0.911 | M9: -0.921 | N9: =(SUM(B9:I9)+SUM(J8:M8))/12 -> 1.5635833
A10: 1879 | B10: -1.005 | C10: -0.729 | D10: -0.445 | E10: -0.447 | F10: -0.956 | G10: -1.18 | H10: -0.827 | I10: -0.607 | J10: -0.523 | K10: -0.557 | L10: -0.72 | M10: -1.031 | N10: =(SUM(B10:I10)+SUM(J9:M9))/12 -> -0.77033333
A11: 1880 | B11: -1.057 | C11: -0.83 | D11: -0.899 | E11: -1.069 | F11: -0.965 | G11: -0.595 | H11: 0.113 | I11: 0.394 | J11: 0.083 | K11: -0.228 | L11: -0.128 | M11: 0.17 | N11: =(SUM(B11:I11)+SUM(J10:M10))/12 -> -0.64491667
A12: 1881 | B12: 0.148 | C12: 0.215 | D12: 0.174 | E12: 0.082 | F12: -0.105 | G12: -0.062 | H12: -0.153 | I12: -0.559 | J12: -0.656 | K12: -0.389 | L12: -0.499 | M12: -0.776 | N12: =(SUM(B12:I12)+SUM(J11:M11))/12 -> -0.03025
A13: 1882 | B13: -0.598 | C13: -0.461 | D13: -0.585 | E13: -0.799 | F13: -1.028 | G13: -0.97 | H13: -0.686 | I13: -0.436 | J13: -0.267 | K13: -0.261 | L13: -0.379 | M13: -0.404 | N13: =(SUM(B13:I13)+SUM(J12:M12))/12 -> -0.65691667
A14: 1883 | B14: -0.562 | C14: -0.628 | D14: -0.562 | E14: -0.672 | F14: -1.07 | G14: -0.898 | H14: -0.284 | I14: -0.228 | J14: -0.314 | K14: -0.01 | L14: 0.004 | M14: -0.012 | N14: =(SUM(B14:I14)+SUM(J13:M13))/12 -> -0.51791667
... A154: 2023 | B154: -1.11 | C154: -0.91 | D154: -0.76 | E154: -0.37 | F154: -0.06 | G154: 0.43 | H154: 0.5 | I154: 0.51 | J154: 0.68 | K154: 0.48 | L154: 0.91 | M154: 1.13 | N154: =(SUM(B154:I154)+SUM(J153:M153))/12 -> -0.67
A155: =meiv2!A47 -> 2024 | B155: =meiv2!B47 -> 0.7 | C155: =meiv2!C47 -> 0.68 | D155: =meiv2!D47 -> 0.78 | E155: =meiv2!E47 -> 0.34 | F155: =meiv2!F47 -> 0.12 | G155: =meiv2!G47 -> -0.23 | H155: =meiv2!H47 -> -0.72 | ... M155: =meiv2!M47 -> -0.91 | N155: =(SUM(B155:I155)+SUM(J154:M154))/12 -> 0.345
A156: =meiv2!A48 -> 2025 | B156: =meiv2!B48 -> -1 | C156: =meiv2!C48 -> -0.83 | D156: =meiv2!D48 -> -0.68 | E156: =meiv2!E48 -> -0.38 | F156: =meiv2!F48 -> -0.36 | G156: =meiv2!G48 -> -1.17 | H156: =meiv2!H48 -> -1.22 | ... M156: =meiv2!M48 -> -0.77 | N156: =(SUM(B156:I156)+SUM(J155:M155))/12 -> -0.77166667
A157: =meiv2!A49 -> 2026 | B157: =meiv2!B49 -> -0.76 | C157: =meiv2!C49 -> -0.95 | D157: =meiv2!D49 -> -1.03 | E157: =meiv2!E49 -> -0.64 | F157: =meiv2!F49 -> 0.27 | G157: =meiv2!G49 -> 1.52 | H157: =meiv2!H49 -> 2.41 | I157: =meiv2!I49 -> 2.54 | J157: AAA
