Workbook

Sheet toyKFmodelData8c
A1: 1850 | B1: -0.42648312 | C1: ='[1]ERF_best_aggregates_1750-2024'!AA102 -> 288.23704 | D1: 3.6 | E1: 0.086558442 | F1: 0 | G1: =G$184 -> 50.219411 | H1: ='[1]ERF_best_aggregates_1750-2024'!AE102 -> -0.08262261 | I1: {=TRANSPOSE(L42:GF42)/4} -> 340.44589
A2: 1851 | B2: -0.2635183 | C2: ='[1]ERF_best_aggregates_1750-2024'!AA103 -> 288.2187 | D2: 2.5083333 | E2: 0.087122259 | F2: 0 | G2: =G$184 -> 50.219411 | H2: ='[1]ERF_best_aggregates_1750-2024'!AE103 -> -0.074346854 | I2: 340.4303
A3: 1852 | B3: -0.22405294 | C3: ='[1]ERF_best_aggregates_1750-2024'!AA104 -> 288.29346 | D3: 1.4416667 | E3: 0.082300038 | F3: 0 | G3: =G$184 -> 50.219411 | H3: ='[1]ERF_best_aggregates_1750-2024'!AE104 -> -0.071212116 | I3: 340.41904
A4: 1853 | B4: -0.26234877 | C4: ='[1]ERF_best_aggregates_1750-2024'!AA105 -> 288.4659 | D4: 0.61666667 | E4: 0.079540539 | F4: 0 | G4: =G$184 -> 50.219411 | H4: ='[1]ERF_best_aggregates_1750-2024'!AE105 -> -0.075491193 | I4: 340.38434
A5: 1854 | B5: -0.29358405 | C5: ='[1]ERF_best_aggregates_1750-2024'!AA106 -> 288.74847 | D5: 0.28333333 | E5: 0.068980705 | F5: 0 | G5: =G$184 -> 50.219411 | H5: ='[1]ERF_best_aggregates_1750-2024'!AE106 -> -0.091699698 | I5: 340.34076
A6: 1855 | B6: -0.29138646 | C6: ='[1]ERF_best_aggregates_1750-2024'!AA107 -> 288.83009 | D6: 2.0333333 | E6: 0.067710675 | F6: 0 | G6: =G$184 -> 50.219411 | H6: ='[1]ERF_best_aggregates_1750-2024'!AE107 -> -0.086573276 | I6: 340.29764
A7: 1856 | B7: -0.32809034 | C7: ='[1]ERF_best_aggregates_1750-2024'!AA108 -> 288.88936 | D7: 38.658333 | E7: 0.072110575 | F7: 0 | G7: =G$184 -> 50.219411 | H7: ='[1]ERF_best_aggregates_1750-2024'!AE108 -> -0.088479988 | I7: 340.28876
A8: 1857 | B8: -0.46585593 | C8: ='[1]ERF_best_aggregates_1750-2024'!AA109 -> 289.23436 | D8: 60.166667 | E8: 0.075915982 | F8: 0 | G8: =G$184 -> 50.219411 | H8: ='[1]ERF_best_aggregates_1750-2024'!AE109 -> -0.095319325 | I8: 340.32849
A9: 1858 | B9: -0.3967561 | C9: ='[1]ERF_best_aggregates_1750-2024'!AA110 -> 289.49979 | D9: 29 | E9: 0.075354932 | F9: 0 | G9: =G$184 -> 50.219411 | H9: ='[1]ERF_best_aggregates_1750-2024'!AE110 -> -0.099661231 | I9: 340.40457
A10: 1859 | B10: -0.29197732 | C10: ='[1]ERF_best_aggregates_1750-2024'!AA111 -> 289.67402 | D10: 11.183333 | E10: 0.071113728 | F10: 0 | G10: =G$184 -> 50.219411 | H10: ='[1]ERF_best_aggregates_1750-2024'!AE111 -> -0.10222859 | I10: 340.47235
A11: 1860 | B11: -0.40712935 | C11: ='[1]ERF_best_aggregates_1750-2024'!AA112 -> 289.91823 | D11: 4.5916667 | E11: 0.075532525 | F11: 0 | G11: =G$184 -> 50.219411 | H11: ='[1]ERF_best_aggregates_1750-2024'!AE112 -> -0.10750809 | I11: 340.4928
A12: 1861 | B12: -0.4636966 | C12: ='[1]ERF_best_aggregates_1750-2024'!AA113 -> 290.26042 | D12: 3.4083333 | E12: 0.08527384 | F12: 0 | G12: =G$184 -> 50.219411 | H12: ='[1]ERF_best_aggregates_1750-2024'!AE113 -> -0.10837089 | I12: 340.46646
A13: 1862 | B13: -0.5548254 | C13: ='[1]ERF_best_aggregates_1750-2024'!AA114 -> 290.47889 | D13: 13.658333 | E13: 0.08448807 | F13: 0 | G13: =G$184 -> 50.219411 | H13: ='[1]ERF_best_aggregates_1750-2024'!AE114 -> -0.10850063 | I13: 340.44412
... A16: 1865 | B16: -0.39224166 | C16: ='[1]ERF_best_aggregates_1750-2024'!AA117 -> 291.53084 | D16: 2 | E16: 0.09969487 | F16: 0 | G16: =G$184 -> 50.219411 | H16: ='[1]ERF_best_aggregates_1750-2024'!AE117 -> -0.12368819 | I16: 340.35919
A17: 1866 | B17: -0.4001619 | C17: ='[1]ERF_best_aggregates_1750-2024'!AA118 -> 291.82365 | D17: 0.825 | E17: 0.098062295 | F17: 0 | G17: =G$184 -> 50.219411 | H17: ='[1]ERF_best_aggregates_1750-2024'!AE118 -> -0.12179118 | I17: 340.32669 | EQ17: =ER17-1 -> 2005 | ER17: =ES17-1 -> 2006 | ES17: =ET17-1 -> 2007 | ET17: =EU17-1 -> 2008 | EU17: =EV17-1 -> 2009 | EV17: =EW17-1 -> 2010 | EW17: =EX17-1 -> 2011 | EX17: =EY17-1 -> 2012 | ... FC17: =FD17-1 -> 2017 | FD17: 2018
A18: 1867 | B18: -0.39941457 | C18: ='[1]ERF_best_aggregates_1750-2024'!AA119 -> 292.26112 | D18: 0.36666667 | E18: 0.10093699 | F18: 0 | G18: =G$184 -> 50.219411 | H18: ='[1]ERF_best_aggregates_1750-2024'!AE119 -> -0.13258649 | I18: 340.30014 | K18: Zanna 2018 | L18: 0 | M18: 1.152174 | N18: 3.055448 | O18: 1.713526 | P18: 1.624636 | Q18: 0.016767 | R18: 3.470358 | S18: 9.072875 | T18: 13.960433 | U18: 17.407888 | V18: 21.636983 | W18: 19.125768 | X18: 16.527455 | Y18: 15.617733 | Z18: 14.757101 | AA18: 14.922197 | AB18: 16.212654 | AC18: 17.683049 | AD18: 18.085829 | AE18: 17.171818 | AF18: 16.535898 | AG18: 15.380051 | AH18: 13.8487 | AI18: 12.512436 | AJ18: 15.250814 | AK18: 19.174388 | AL18: 22.765411 | AM18: 25.369513 | AN18: 30.661798 | AO18: 32.826909 | AP18: 29.906303 | AQ18: 24.750119 | AR18: 16.52974 | AS18: 6.202032 | AT18: -2.972809 | AU18: -10.435316 | AV18: -17.45549 | AW18: -21.520154 | AX18: -26.003014 | AY18: -32.254265 | AZ18: -37.908706 | BA18: -40.699373 | BB18: -42.468967 | BC18: -39.558381 | BD18: -33.405565 | BE18: -29.332003 | BF18: -25.898116 | BG18: -23.093303 | BH18: -22.862689 | BI18: -25.094347 | BJ18: -25.852486 | BK18: -28.246202 | BL18: -29.848146 | BM18: -32.924574 | BN18: -32.588192 | BO18: -28.764911 | BP18: -23.708613 | BQ18: -19.774637 | BR18: -15.226844 | BS18: -11.34996 | BT18: -8.957786 | BU18: -5.661382 | BV18: -1.364168 | BW18: 2.793185 | BX18: 5.869318 | BY18: 11.234539 | BZ18: 19.853909 | CA18: 30.033243 | CB18: 39.926427 | CC18: 49.824919 | CD18: 59.743278 | CE18: 67.517431 | CF18: 77.93809 | CG18: 92.961553 | CH18: 105.09258 | CI18: 107.77882 | CJ18: 108.85972 | CK18: 107.21289 | CL18: 101.69687 | CM18: 99.013982 | CN18: 105.47594 | CO18: 115.27586 | CP18: 122.90332 | CQ18: 126.5047 | CR18: 128.33549 | CS18: 129.66937 | CT18: 133.23209 | CU18: 138.87055 | CV18: 147.99471 | CW18: 158.04931 | CX18: 166.67939 | CY18: 170.15124 | CZ18: 170.21562 | DA18: 166.12664 | DB18: 163.16833 | DC18: 160.95305 | DD18: 159.30754 | DE18: 161.72691 | DF18: 170.2651 | DG18: 173.85688 | DH18: 174.00965 | DI18: 176.92966 | DJ18: 177.00977 | DK18: 172.98574 | DL18: 171.97073 | DM18: 175.8085 | DN18: 180.62356 | DO18: 187.51975 | DP18: 200.02892 | DQ18: 214.22823 | DR18: 224.42046 | DS18: 229.07346 | DT18: 234.39847 | DU18: 235.26143 | DV18: 235.105 | DW18: 238.01264 | DX18: 246.14991 | DY18: 252.45115 | DZ18: 260.93968 | EA18: 270.28614 | EB18: 275.88284 | EC18: 276.58821 | ED18: 279.07423 | EE18: 282.20069 | EF18: 286.93273 | EG18: 296.39127 | EH18: 312.10352 | EI18: 325.80344 | EJ18: 334.27249 | EK18: 341.25049 | EL18: 348.03345 | EM18: 351.25772 | EN18: 357.03793 | EO18: 367.89013 | EP18: 378.32559 | EQ18: 385.50961 | ER18: 389.38557 | ES18: 391.97982 | ET18: 395.58442 | EU18: 399.40767 | EV18: 403.10555 | EW18: 409.97602 | EX18: 417.5157 | EY18: 425.15174 | EZ18: 433.95853 | FA18: 444.16808 | FB18: 453.15947 | FC18: 460.30365 | FD18: 463.99003
A19: 1868 | B19: -0.36312076 | C19: ='[1]ERF_best_aggregates_1750-2024'!AA120 -> 292.69957 | D19: 0.20833333 | E19: 0.091737048 | F19: 0 | G19: =G$184 -> 50.219411 | H19: ='[1]ERF_best_aggregates_1750-2024'!AE120 -> -0.14384636 | I19: 340.35177 | K19: https://zenodo.org/records/4603700#.ZDuFNxXMI88 | L19: 47.877714 | M19: 47.296132 | N19: 49.162493 | O19: 52.026752 | P19: 52.084695 | Q19: 56.097728 | R19: 49.577996 | S19: 49.734915 | T19: 49.318906 | U19: 50.905978 | V19: 50.942965 | W19: 48.384266 | X19: 51.583947 | Y19: 47.446891 | Z19: 48.134172 | AA19: 50.271923 | AB19: 53.832246 | AC19: 49.341672 | AD19: 50.638702 | AE19: 49.728126 | AF19: 51.957317 | AG19: 50.066094 | AH19: 54.553121 | AI19: 49.33589 | AJ19: 51.153911 | AK19: 48.515118 | AL19: 58.411089 | AM19: 51.211101 | AN19: 48.897539 | AO19: 47.410651 | AP19: 55.610861 | AQ19: 50.779745 | AR19: 48.623297 | AS19: 50.851572 | AT19: 53.647177 | AU19: 46.205308 | AV19: 54.434851 | AW19: 47.731118 | AX19: 52.426806 | AY19: 51.183776 | AZ19: 49.505871 | BA19: 51.733893 | BB19: 48.463394 | BC19: 47.801648 | BD19: 53.261487 | BE19: 51.317435 | BF19: 49.731985 | BG19: 50.709682 | BH19: 50.593136 | BI19: 49.813271 | BJ19: 48.289882 | BK19: 38.332555 | BL19: 36.775419 | BM19: 35.377609 | BN19: 40.943997 | BO19: 41.31503 | BP19: 38.726614 | BQ19: 39.926903 | BR19: 39.68572 | BS19: 37.050845 | BT19: 36.781007 | BU19: 37.912699 | BV19: 38.055422 | BW19: 37.68018 | BX19: 41.302841 | BY19: 35.018914 | BZ19: 38.775016 | CA19: 35.837446 | CB19: 40.31908 | CC19: 38.963685 | CD19: 36.418633 | CE19: 38.579852 | CF19: 37.244673 | CG19: 37.659891 | CH19: 36.08115 | CI19: 34.400259 | CJ19: 40.178642 | CK19: 37.147046 | CL19: 37.950192 | CM19: 36.549625 | CN19: 37.305274 | CO19: 37.817529 | CP19: 38.384177 | CQ19: 40.473965 | CR19: 37.5954 | CS19: 34.225226 | CT19: 36.874388 | CU19: 39.492299 | CV19: 41.305689 | CW19: 37.915106 | CX19: 38.643114 | CY19: 38.403932 | CZ19: 38.867451 | DA19: 39.016264 | DB19: 39.950174 | DC19: 36.976562 | DD19: 40.128589 | DE19: 40.475253 | DF19: 39.266279 | DG19: 39.494076 | DH19: 25.001082 | DI19: 25.240618 | DJ19: 25.880512 | DK19: 26.163758 | DL19: 26.129288 | DM19: 25.307863 | DN19: 24.080274 | DO19: 24.397352 | DP19: 26.478678 | DQ19: 24.964443 | DR19: 26.393549 | DS19: 26.34393 | DT19: 26.269539 | DU19: 25.639737 | DV19: 25.283627 | DW19: 25.716423 | DX19: 25.471305 | DY19: 24.145945 | DZ19: 24.556968 | EA19: 26.405666 | EB19: 24.162634 | EC19: 25.433071 | ED19: 28.731781 | EE19: 23.850376 | EF19: 23.981631 | EG19: 25.697915 | EH19: 25.636693 | EI19: 25.646369 | EJ19: 26.810634 | EK19: 23.972168 | EL19: 25.699831 | EM19: 24.638421 | EN19: 24.003787 | EO19: 25.470211 | EP19: 26.016723 | EQ19: 25.435933 | ER19: 25.604416 | ES19: 23.583464 | ET19: 26.338853 | EU19: 25.861285 | EV19: 26.677227 | EW19: 26.216131 | EX19: 23.723237 | EY19: 24.557425 | EZ19: 26.02901 | FA19: 24.026637 | FB19: 24.026688 | FC19: 26.532469 | FD19: 24.110208
A20: 1869 | B20: -0.31852213 | C20: ='[1]ERF_best_aggregates_1750-2024'!AA121 -> 292.84071 | D20: 0.6 | E20: 0.080809103 | F20: 0 | G20: =G$184 -> 50.219411 | H20: ='[1]ERF_best_aggregates_1750-2024'!AE121 -> -0.14181872 | I20: 340.42279
A21: 1870 | B21: -0.32778123 | C21: ='[1]ERF_best_aggregates_1750-2024'!AA122 -> 293.13105 | D21: 0.60833333 | E21: 0.073627265 | F21: {=TRANSPOSE(L18:FD18)} -> 0 | G21: {=TRANSPOSE(L19:FD19)} -> 47.877714 | H21: ='[1]ERF_best_aggregates_1750-2024'!AE122 -> -0.15037133 | I21: 340.51199
A22: 1871 | B22: -0.37342322 | C22: ='[1]ERF_best_aggregates_1750-2024'!AA123 -> 293.20138 | D22: 0.59166667 | E22: 0.075082032 | F22: 1.152174 | G22: 47.296132 | H22: ='[1]ERF_best_aggregates_1750-2024'!AE123 -> -0.1482451 | I22: 340.50793
A23: 1872 | B23: -0.30945122 | C23: ='[1]ERF_best_aggregates_1750-2024'!AA124 -> 293.29319 | D23: 1.3166667 | E23: 0.06818233 | F23: 3.055448 | G23: 49.162493 | H23: ='[1]ERF_best_aggregates_1750-2024'!AE124 -> -0.15060728 | I23: 340.49283 | K23: Boyer NOAA | L23: heat_content_anomaly_0-2000_yearly.nc | M23: =1955+606/12 -> 2005.5 | N23: =M23+1 -> 2006.5 | O23: =N23+1 -> 2007.5 | P23: =O23+1 -> 2008.5 | Q23: =P23+1 -> 2009.5 | R23: =Q23+1 -> 2010.5 | S23: =R23+1 -> 2011.5 | T23: =S23+1 -> 2012.5 | U23: =T23+1 -> 2013.5 | ... AE23: =AD23+1 -> 2023.5
A24: 1873 | B24: -0.32117823 | C24: ='[1]ERF_best_aggregates_1750-2024'!AA125 -> 293.61917 | D24: 3.0083333 | E24: 0.06510575 | F24: 1.713526 | G24: 52.026752 | H24: ='[1]ERF_best_aggregates_1750-2024'!AE125 -> -0.16629871 | I24: 340.45068 | K24: https://www.ncei.noaa.gov/products/climate-data-records/global-ocean-heat-content | L24: https://www.ncei.noaa.gov/data/oceans/ncei/archive/data/0164586/derived/ | M24: 10.171 | N24: 12.638 | O24: 12.394 | P24: 13.257 | Q24: 13.431 | R24: 14.537 | S24: 15.394 | T24: 16.187 | U24: 18.65 | V24: 20.110001 | W24: 22.400999 | X24: 20.799 | Y24: 23.589001 | Z24: 24.059 | AA24: 25.436001 | AB24: 25.525 | AC24: 27.280001 | AD24: 28.191999 | AE24: 29.105
A25: 1874 | B25: -0.36541122 | C25: ='[1]ERF_best_aggregates_1750-2024'!AA126 -> 293.90688 | D25: 1.9583333 | E25: 0.066028365 | F25: 1.624636 | G25: 52.084695 | H25: ='[1]ERF_best_aggregates_1750-2024'!AE126 -> -0.17064407 | I25: 340.39374 | M25: =(N24-M24)*10 -> 24.67 | N25: =(O24-N24)*10 -> -2.44 | O25: =(P24-O24)*10 -> 8.63 | P25: =(Q24-P24)*10 -> 1.74 | Q25: =(R24-Q24)*10 -> 11.06 | R25: =(S24-R24)*10 -> 8.57 | S25: =(T24-S24)*10 -> 7.93 | T25: =(U24-T24)*10 -> 24.63 | ... AD25: =(AE24-AD24)*10 -> 9.13001
A26: 1875 | B26: -0.3667476 | C26: ='[1]ERF_best_aggregates_1750-2024'!AA127 -> 294.05739 | D26: 1.2916667 | E26: 0.068345515 | F26: 0.016767 | G26: 56.097728 | H26: ='[1]ERF_best_aggregates_1750-2024'!AE127 -> -0.16763622 | I26: 340.33819
A27: 1876 | B27: -0.41084635 | C27: ='[1]ERF_best_aggregates_1750-2024'!AA128 -> 294.28922 | D27: 6.2 | E27: 0.069553075 | F27: 3.470358 | G27: 49.577996 | H27: ='[1]ERF_best_aggregates_1750-2024'!AE128 -> -0.17429313 | I27: 340.32459 | M27: =EQ17 -> 2005 | N27: =ER17 -> 2006 | O27: =ES17 -> 2007 | P27: =ET17 -> 2008 | Q27: =EU17 -> 2009 | R27: =EV17 -> 2010 | S27: =EW17 -> 2011 | T27: =EX17 -> 2012 | ... AE27: =FI17 -> 0
A28: 1877 | B28: -0.082424335 | C28: ='[1]ERF_best_aggregates_1750-2024'!AA129 -> 294.61231 | D28: 5.2666667 | E28: 0.063936372 | F28: 9.072875 | G28: 49.734915 | H28: ='[1]ERF_best_aggregates_1750-2024'!AE129 -> -0.17938792 | I28: 340.32764 | K28: Rep Zanna18 | M28: =EQ18 -> 385.50961 | N28: =ER18 -> 389.38557 | O28: =ES18 -> 391.97982 | P28: =ET18 -> 395.58442 | Q28: =EU18 -> 399.40767 | R28: =EV18 -> 403.10555 | S28: =EW18 -> 409.97602 | T28: =EX18 -> 417.5157 | ... Z28: =FD18 -> 463.99003 | AA28: =Z28+Z33 -> 477.76004 | AB28: =AA28+AA33 -> 478.65003 | AC28: =AB28+AB33 -> 496.20004 | AD28: =AC28+AC33 -> 505.32002 | AE28: =AD28+AD33 -> 514.45003
A29: 1878 | B29: 0.010314008 | C29: ='[1]ERF_best_aggregates_1750-2024'!AA130 -> 294.92873 | D29: 3.1583333 | E29: 0.06155574 | F29: 13.960433 | G29: 49.318906 | H29: ='[1]ERF_best_aggregates_1750-2024'!AE130 -> -0.1832961 | I29: 340.29495 | M29: =N28-M28 -> 3.875953 | N29: =O28-N28 -> 2.594248 | O29: =P28-O28 -> 3.604608 | P29: =Q28-P28 -> 3.823247 | Q29: =R28-Q28 -> 3.697881 | R29: =S28-R28 -> 6.870471 | S29: =T28-S28 -> 7.539676 | T29: =U28-T28 -> 7.636045 | ... Y29: =Z28-Y28 -> 3.686381
A30: 1879 | B30: -0.28873557 | C30: ='[1]ERF_best_aggregates_1750-2024'!AA131 -> 295.19922 | D30: 2 | E30: 0.06592058 | F30: 17.407888 | G30: 50.905978 | H30: ='[1]ERF_best_aggregates_1750-2024'!AE131 -> -0.19487011 | I30: 340.30615
A31: 1880 | B31: -0.3031736 | C31: ='[1]ERF_best_aggregates_1750-2024'!AA132 -> 295.45641 | D31: 1.1416667 | E31: 0.061261195 | F31: 21.636983 | G31: 50.942965 | H31: ='[1]ERF_best_aggregates_1750-2024'!AE132 -> -0.20480285 | I31: 340.37341
A32: 1881 | B32: -0.2130113 | C32: ='[1]ERF_best_aggregates_1750-2024'!AA133 -> 295.87207 | D32: 0.66666667 | E32: 0.062508651 | F32: 19.125768 | G32: 48.384266 | H32: ='[1]ERF_best_aggregates_1750-2024'!AE133 -> -0.21030738 | I32: 340.43732
A33: 1882 | B33: -0.27210787 | C33: ='[1]ERF_best_aggregates_1750-2024'!AA134 -> 296.1325 | D33: 0.575 | E33: 0.062595312 | F33: 16.527455 | G33: 51.583947 | H33: ='[1]ERF_best_aggregates_1750-2024'!AE134 -> -0.21437935 | I33: 340.42929 | M33: =(Y24-M24)*10 -> 134.18001 | N33: much larger 2005-2018 in Boyer NOAA - nearly double | Z33: =Z25 -> 13.77001 | AA33: =AA25 -> 0.88999 | AB33: =AB25 -> 17.55001 | AC33: =AC25 -> 9.11998 | AD33: =AD25 -> 9.13001
A34: 1883 | B34: -0.32755712 | C34: ='[1]ERF_best_aggregates_1750-2024'!AA135 -> 296.35268 | D34: 47.291667 | E34: 0.055816838 | F34: 15.617733 | G34: 47.446891 | H34: ='[1]ERF_best_aggregates_1750-2024'!AE135 -> -0.21511301 | I34: 340.41818 | M34: =Z28-M28 -> 78.480415 | N34: Confirmed in AR6 fig 2.26
A35: 1884 | B35: -0.47444913 | C35: ='[1]ERF_best_aggregates_1750-2024'!AA136 -> 296.80515 | D35: 142.90833 | E35: 0.054527167 | F35: 14.757101 | G35: 48.134172 | H35: ='[1]ERF_best_aggregates_1750-2024'!AE136 -> -0.22299133 | I35: 340.43396 | Z35: =AA36-Z36 -> 14.374416 | AA35: =AB36-AA36 -> 1.1049574 | AB35: =AC36-AB36 -> 19.889233 | AC35: =AD36-AC36 -> 9.9446166 | AD35: =AE36-AD36 -> -509.30325
A36: 1885 | B36: -0.45813233 | C36: ='[1]ERF_best_aggregates_1750-2024'!AA137 -> 297.17879 | D36: 63.491667 | E36: 0.054673667 | F36: 14.922197 | G36: 50.271923 | H36: ='[1]ERF_best_aggregates_1750-2024'!AE137 -> -0.22729413 | I36: 340.40936 | L36: =M33/M34 -> 1.7097261 | Z36: =F169 -> 463.99003 | AA36: 478.36445 | AB36: 479.4694 | AC36: 499.35864 | AD36: 509.30325
A37: 1886 | B37: -0.4081737 | C37: ='[1]ERF_best_aggregates_1750-2024'!AA138 -> 297.57712 | D37: 36.433333 | E37: 0.052311525 | F37: 16.212654 | G37: 53.832246 | H37: ='[1]ERF_best_aggregates_1750-2024'!AE138 -> -0.22674831 | I37: 340.34473
A38: 1887 | B38: -0.48834157 | C38: ='[1]ERF_best_aggregates_1750-2024'!AA139 -> 298.06831 | D38: 37.108333 | E38: 0.057341585 | F38: 17.683049 | G38: 49.341672 | H38: ='[1]ERF_best_aggregates_1750-2024'!AE139 -> -0.23731968 | I38: 340.3168
A39: 1888 | B39: -0.37258717 | C39: ='[1]ERF_best_aggregates_1750-2024'!AA140 -> 298.64463 | D39: 21.858333 | E39: 0.05874657 | F39: 18.085829 | G39: 50.638702 | H39: ='[1]ERF_best_aggregates_1750-2024'!AE140 -> -0.26036188 | I39: 340.3016
A40: 1889 | B40: -0.250402 | C40: ='[1]ERF_best_aggregates_1750-2024'!AA141 -> 299.05599 | D40: 28.533333 | E40: 0.061829255 | F40: 17.171818 | G40: 49.728126 | H40: ='[1]ERF_best_aggregates_1750-2024'!AE141 -> -0.25676585 | I40: 340.30023 | L40: 1850 | M40: =L40+1 -> 1851 | N40: =M40+1 -> 1852 | O40: =N40+1 -> 1853 | P40: =O40+1 -> 1854 | Q40: =P40+1 -> 1855 | R40: =Q40+1 -> 1856 | S40: =R40+1 -> 1857 | T40: =S40+1 -> 1858 | ... GC40: =GB40+1 -> 2023
A41: 1890 | B41: -0.5002501 | C41: ='[1]ERF_best_aggregates_1750-2024'!AA142 -> 299.58899 | D41: 39.125 | E41: 0.062296785 | F41: 16.535898 | G41: 51.957317 | H41: ='[1]ERF_best_aggregates_1750-2024'!AE142 -> -0.27440501 | I41: 340.30221 | L41: 1360.7638 | M41: 1360.7661 | N41: 1360.7635 | O41: 1360.6677 | P41: 1360.5201 | Q41: 1360.4224 | R41: 1360.3945 | S41: 1360.4717 | T41: 1360.6649 | U41: 1360.8915 | V41: 1360.9705 | W41: 1360.8665 | X41: 1360.7474 | Y41: 1360.6658 | Z41: 1360.6586 | AA41: 1360.5726 | AB41: 1360.5129 | AC41: 1360.4227 | AD41: 1360.5715 | AE41: 1360.8141 | AF41: 1361.0688 | AG41: 1361.0037 | AH41: 1360.9293 | AI41: 1360.7247 | AJ41: 1360.5881 | AK41: 1360.4443 | AL41: 1360.4117 | AM41: 1360.4122 | AN41: 1360.3529 | AO41: 1360.3329 | AP41: 1360.4572 | AQ41: 1360.5952 | AR41: 1360.5134 | AS41: 1360.4916 | AT41: 1360.6516 | AU41: 1360.5322 | AV41: 1360.3662 | AW41: 1360.3097 | AX41: 1360.2631 | AY41: 1360.2515 | AZ41: 1360.2816 | BA41: 1360.5386 | BB41: 1360.6478 | BC41: 1360.8162 | BD41: 1360.9304 | BE41: 1360.7867 | BF41: 1360.5797 | BG41: 1360.4427 | BH41: 1360.4139 | BI41: 1360.3433 | BJ41: 1360.3202 | BK41: 1360.2567 | BL41: 1360.2842 | BM41: 1360.4728 | BN41: 1360.7462 | BO41: 1360.5734 | BP41: 1360.7678 | BQ41: 1360.6509 | BR41: 1360.7117 | BS41: 1360.5845 | BT41: 1360.4545 | BU41: 1360.3549 | BV41: 1360.3066 | BW41: 1360.3071 | BX41: 1360.4119 | BY41: 1360.7261 | BZ41: 1360.959 | CA41: 1361.1509 | CB41: 1361.1011 | CC41: 1360.839 | CD41: 1360.6461 | CE41: 1360.5411 | CF41: 1360.4413 | CG41: 1360.4375 | CH41: 1360.5037 | CI41: 1360.7192 | CJ41: 1360.8359 | CK41: 1361.0249 | CL41: 1360.8993 | CM41: 1360.8456 | CN41: 1360.8109 | CO41: 1360.6818 | CP41: 1360.5666 | CQ41: 1360.4906 | CR41: 1360.5598 | CS41: 1360.7996 | CT41: 1361.2286 | CU41: 1361.205 | CV41: 1361.1284 | CW41: 1361.0916 | CX41: 1360.9985 | CY41: 1360.9114 | CZ41: 1360.791 | DA41: 1360.6261 | DB41: 1360.673 | DC41: 1360.9412 | DD41: 1361.0884 | DE41: 1361.3927 | DF41: 1361.5063 | DG41: 1361.4088 | DH41: 1361.1179 | DI41: 1360.8497 | DJ41: 1360.8224 | DK41: 1360.6938 | DL41: 1360.7009 | DM41: 1360.8811 | DN41: 1361.4214 | DO41: 1361.9398 | DP41: 1361.861 | DQ41: 1361.5613 | DR41: 1361.4275 | DS41: 1360.9957 | DT41: 1360.7981 | DU41: 1360.7325 | DV41: 1360.7277 | DW41: 1360.774 | DX41: 1361.0021 | DY41: 1361.223 | DZ41: 1361.3037 | EA41: 1361.3771 | EB41: 1361.3759 | EC41: 1361.04 | ED41: 1361.1002 | EE41: 1360.8647 | EF41: 1360.771 | EG41: 1360.7155 | EH41: 1360.6946 | EI41: 1360.8905 | EJ41: 1361.2162 | EK41: 1361.6016 | EL41: 1361.6398 | EM41: 1361.6834 | EN41: 1361.2311 | EO41: 1361.2137 | EP41: 1360.7904 | EQ41: 1360.6331 | ER41: 1360.6417 | ES41: 1360.7828 | ET41: 1361.1195 | EU41: 1361.6433 | EV41: 1361.5521 | EW41: 1361.5178 | EX41: 1361.3082 | EY41: 1360.9427 | EZ41: 1360.7419 | FA41: 1360.7317 | FB41: 1360.6763 | FC41: 1360.8073 | FD41: 1361.1759 | FE41: 1361.48 | FF41: 1361.6603 | FG41: 1361.5686 | FH41: 1361.6332 | FI41: 1361.1283 | FJ41: 1360.918 | FK41: 1360.7004 | FL41: 1360.6796 | FM41: 1360.6039 | FN41: 1360.6097 | FO41: 1360.6066 | FP41: 1360.7854 | FQ41: 1361.069 | FR41: 1361.1926 | FS41: 1361.2631 | FT41: 1361.3862 | FU41: 1361.4098 | FV41: 1360.9519 | FW41: 1360.6597 | FX41: 1360.6387 | FY41: 1360.6492 | FZ41: 1360.7491 | GA41: 1360.9749 | GB41: 1361.4944 | GC41: =FT44 -> 1361.8057
A42: 1891 | B42: -0.3975334 | C42: ='[1]ERF_best_aggregates_1750-2024'!AA143 -> 299.95233 | D42: 29.975 | E42: 0.06830345 | F42: 15.380051 | G42: 50.066094 | H42: ='[1]ERF_best_aggregates_1750-2024'!AE143 -> -0.2731797 | I42: 340.37671 | L42: 1361.7836 | M42: 1361.7212 | N42: 1361.6762 | O42: 1361.5374 | P42: 1361.363 | Q42: 1361.1906 | R42: 1361.155 | S42: 1361.314 | T42: 1361.6183 | U42: 1361.8894 | V42: 1361.9712 | W42: 1361.8658 | X42: 1361.7765 | Y42: 1361.6113 | Z42: 1361.554 | AA42: 1361.4368 | AB42: 1361.3068 | AC42: 1361.2006 | AD42: 1361.4071 | AE42: 1361.6912 | AF42: 1362.048 | AG42: 1362.0317 | AH42: 1361.9713 | AI42: 1361.8027 | AJ42: 1361.5749 | AK42: 1361.3528 | AL42: 1361.2983 | AM42: 1361.3105 | AN42: 1361.1798 | AO42: 1361.2246 | AP42: 1361.4936 | AQ42: 1361.7493 | AR42: 1361.7172 | AS42: 1361.6727 | AT42: 1361.7358 | AU42: 1361.6374 | AV42: 1361.3789 | AW42: 1361.2672 | AX42: 1361.2064 | AY42: 1361.2009 | AZ42: 1361.2089 | BA42: 1361.5068 | BB42: 1361.8229 | BC42: 1361.9004 | BD42: 1361.8906 | BE42: 1361.7562 | BF42: 1361.5945 | BG42: 1361.339 | BH42: 1361.3961 | BI42: 1361.2694 | BJ42: 1361.2485 | BK42: 1361.1498 | BL42: 1361.1782 | BM42: 1361.3846 | BN42: 1361.6416 | BO42: 1361.6234 | BP42: 1361.7118 | BQ42: 1361.6744 | BR42: 1361.6483 | BS42: 1361.5477 | BT42: 1361.3435 | BU42: 1361.1946 | BV42: 1361.1765 | BW42: 1361.1562 | BX42: 1361.2395 | BY42: 1361.6466 | BZ42: 1361.7913 | CA42: 1362.1728 | CB42: 1362.041 | CC42: 1361.7353 | CD42: 1361.4721 | CE42: 1361.3773 | CF42: 1361.2399 | CG42: 1361.2076 | CH42: 1361.2931 | CI42: 1361.5048 | CJ42: 1361.6923 | CK42: 1361.8634 | CL42: 1361.8317 | CM42: 1361.6455 | CN42: 1361.5674 | CO42: 1361.4019 | CP42: 1361.2981 | CQ42: 1361.2361 | CR42: 1361.2887 | CS42: 1361.5372 | CT42: 1362.0519 | CU42: 1362.2073 | CV42: 1362.1183 | CW42: 1361.9939 | CX42: 1361.8455 | CY42: 1361.7234 | CZ42: 1361.5128 | DA42: 1361.3309 | DB42: 1361.318 | DC42: 1361.6186 | DD42: 1361.9385 | DE42: 1362.1898 | DF42: 1362.3061 | DG42: 1362.1644 | DH42: 1361.8707 | DI42: 1361.6533 | DJ42: 1361.4714 | DK42: 1361.3473 | DL42: 1361.2745 | DM42: 1361.4337 | DN42: 1361.9768 | DO42: 1362.4329 | DP42: 1362.4039 | DQ42: 1362.0961 | DR42: 1361.9429 | DS42: 1361.557 | DT42: 1361.3755 | DU42: 1361.3164 | DV42: 1361.2967 | DW42: 1361.3314 | DX42: 1361.5267 | DY42: 1361.7355 | DZ42: 1361.7905 | EA42: 1361.8584 | EB42: 1361.8505 | EC42: 1361.5586 | ED42: 1361.6414 | EE42: 1361.4154 | EF42: 1361.3394 | EG42: 1361.2781 | EH42: 1361.2561 | EI42: 1361.4288 | EJ42: 1361.8117 | EK42: 1362.1752 | EL42: 1362.2012 | EM42: 1362.2485 | EN42: 1361.8069 | EO42: 1361.8102 | EP42: 1361.4021 | EQ42: 1361.2557 | ER42: 1361.2617 | ES42: 1361.3965 | ET42: 1361.7025 | EU42: 1362.2012 | EV42: 1362.12 | EW42: 1362.0124 | EX42: 1361.8814 | EY42: 1361.6144 | EZ42: 1361.3957 | FA42: 1361.3113 | FB42: 1361.2351 | FC42: 1361.3572 | FD42: 1361.7025 | FE42: 1361.9731 | FF42: 1362.2537 | FG42: 1362.0814 | FH42: 1362.1906 | FI42: 1361.6907 | FJ42: 1361.4706 | FK42: 1361.2624 | FL42: 1361.2358 | FM42: 1361.1686 | FN42: 1361.1968 | FO42: 1361.191 | FP42: 1361.3396 | FQ42: 1361.6064 | FR42: 1361.7682 | FS42: 1361.813 | FT42: 1361.8887 | FU42: 1361.949 | FV42: 1361.4648 | FW42: 1361.2914 | FX42: 1361.2624 | FY42: 1361.2555 | FZ42: 1361.3228 | GA42: 1361.4894 | GB42: 1361.9811 | GC42: 1362.4476 | GD42: 1362.5648 | GE42: 1362.4159
...

Sheet ERF source
B1: CO2 | C1: CH4 | D1: N2O | E1: aerosol-radiation_interactions | F1: aerosol-cloud_interactions | G1: O3 | H1: contrails | I1: land_use | J1: BC_on_snow | K1: H2O_stratospheric | L1: solar | M1: volcanic | N1: aerosol | O1: nonco2wmghg | P1: halogen | Q1: anthro | R1: total | S1: minor | Z1: anthro no aerosol | AA1: eCO2 conc | AE1: anthro_cloud+radiation
A2: 1750.5 | B2: 0 | C2: 0 | D2: 0 | E2: 0 | F2: 0 | G2: 0 | H2: 0 | I2: 0 | J2: 0 | K2: 0 | L2: 0.097590262 | M2: 0.20367977 | N2: 0 | O2: 0 | P2: 0 | Q2: 0 | R2: 0.30127003 | S2: 0 | Z2: =K2+J2+I2+H2+G2+D2+C2+B2+P2 -> 0 | AA2: =10^((Z2+$V$100)/$V$99) -> 278.19849 | AE2: =F2+E2 -> 0
A3: 1751.5 | B3: 0.0014172921 | C3: 0.00050833036 | D3: 7.4479984e-05 | E3: 0.00063088451 | F3: 0.0038301063 | G3: -0.0004415655 | H3: 0 | I3: -0.00011361737 | J3: -0.00037354792 | K3: 3.4468963e-05 | L3: 0.079243973 | M3: 0.23732406 | N3: 0.0044609908 | O3: 0.00058281114 | P3: 7.9580096e-10 | Q3: 0.0055668322 | R3: 0.32213486 | S3: -0.00045269633 | Z3: =K3+J3+I3+H3+G3+D3+C3+B3+P3 -> 0.0011058414 | AA3: =10^((Z3+$V$100)/$V$99) -> 278.25409 | AE3: =F3+E3 -> 0.0044609908
A4: 1752.5 | B4: 0.0028342465 | C4: 0.0010163535 | D4: 0.00014895163 | E4: 0.0011555409 | F4: 0.0055754332 | G4: -0.00040980111 | H4: 0 | I4: -0.00023001732 | J4: -0.00049819633 | K4: 6.8937925e-05 | L4: 0.049166043 | M4: 0.24006953 | N4: 0.0067309741 | O4: 0.0011653067 | P4: 1.5916019e-09 | Q4: 0.0096614505 | R4: 0.29889702 | S4: -0.00065927572 | Z4: =K4+J4+I4+H4+G4+D4+C4+B4+P4 -> 0.0029304764 | AA4: =10^((Z4+$V$100)/$V$99) -> 278.34584 | AE4: =F4+E4 -> 0.0067309741
A5: 1753.5 | B5: 0.0042508635 | C5: 0.0015240699 | D5: 0.00022341493 | E5: 0.00063743664 | F5: 0.0038590069 | G5: -0.00014890974 | H5: 0 | I5: -0.00034910088 | J5: -0.00037360606 | K5: 0.00010340689 | L5: 0.012988284 | M5: 0.091163618 | N5: 0.0044964435 | O5: 0.0017474872 | P5: 2.3874029e-09 | Q5: 0.0097265844 | R5: 0.11387849 | S5: -0.00061930005 | Z5: =K5+J5+I5+H5+G5+D5+C5+B5+P5 -> 0.0052301409 | AA5: =10^((Z5+$V$100)/$V$99) -> 278.46152 | AE5: =F5+E5 -> 0.0044964435
A6: 1754.5 | B6: 0.0056671431 | C6: 0.0020314801 | D6: 0.00029786991 | E6: -0.00053103925 | F6: -0.00097612658 | G6: 0.00074659103 | H6: 0 | I6: -0.00047081885 | J6: 5.4014287e-05 | K6: 0.00013787585 | L6: -0.021426608 | M6: -0.071972964 | N6: -0.0015071658 | O6: 0.0023293532 | P6: 3.1832038e-09 | Q6: 0.0069569927 | R6: -0.08644258 | S6: -0.00027892872 | Z6: =K6+J6+I6+H6+G6+D6+C6+B6+P6 -> 0.0084641586 | AA6: =10^((Z6+$V$100)/$V$99) -> 278.62429 | AE6: =F6+E6 -> -0.0015071658
A7: 1755.5 | B7: 0.0070830855 | C7: 0.0025385845 | D7: 0.00037231656 | E7: 0.00047903358 | F7: 0.00015622248 | G7: 0.0010370261 | H7: 0 | I7: -0.00059519151 | J7: 5.8738608e-05 | K7: 0.00017234481 | L7: -0.045903927 | M7: 0.086290159 | N7: 0.00063525606 | O7: 0.002910905 | P7: 3.9790048e-09 | Q7: 0.011302165 | R7: 0.051688396 | S7: -0.00036410809 | Z7: =K7+J7+I7+H7+G7+D7+C7+B7+P7 -> 0.010666909 | AA7: =10^((Z7+$V$100)/$V$99) -> 278.73521 | AE7: =F7+E7 -> 0.00063525606
A8: 1756.5 | B8: 0.008498691 | C8: 0.0030453837 | D8: 0.00044675488 | E8: 0.00048227067 | F8: 0.0037957511 | G8: 0.0002077778 | H8: 0 | I8: -0.00072213678 | J8: -0.00039829679 | K8: 0.00020681378 | L8: -0.053485812 | M8: -0.035536597 | N8: 0.0042780218 | O8: 0.0034921433 | P8: 4.7748058e-09 | Q8: 0.015563014 | R8: -0.073459395 | S8: -0.00091361979 | Z8: =K8+J8+I8+H8+G8+D8+C8+B8+P8 -> 0.011284992 | AA8: =10^((Z8+$V$100)/$V$99) -> 278.76634 | AE8: =F8+E8 -> 0.0042780218
A9: 1757.5 | B9: 0.0099139597 | C9: 0.003551878 | D9: 0.00052118489 | E9: 2.7196971e-05 | F9: -0.0054374544 | G9: 0.0027551041 | H9: 0 | I9: -0.0008516726 | J9: 0.00082075632 | K9: 0.00024128274 | L9: -0.034343893 | M9: 0.19284791 | N9: -0.0054102574 | O9: 0.0040730685 | P9: 5.5706067e-09 | Q9: 0.011542241 | R9: 0.17004626 | S9: 0.00021036646 | Z9: =K9+J9+I9+H9+G9+D9+C9+B9+P9 -> 0.016952499 | AA9: =10^((Z9+$V$100)/$V$99) -> 279.05196 | AE9: =F9+E9 -> -0.0054102574
A10: 1758.5 | B10: 0.011328892 | C10: 0.0040580681 | D10: 0.00059560658 | E10: 0.00023281521 | F10: -0.0020102047 | G10: 0.0023343907 | H10: 0 | I10: -0.00098378121 | J10: 0.0004093226 | K10: 0.0002757517 | L10: 0.017013236 | M10: 0.23767116 | N10: -0.0017773895 | O10: 0.0046536811 | P10: 6.3664077e-09 | Q10: 0.016240867 | R10: 0.27092526 | S10: -0.00029870691 | Z10: =K10+J10+I10+H10+G10+D10+C10+B10+P10 -> 0.018018257 | AA10: =10^((Z10+$V$100)/$V$99) -> 279.1057 | AE10: =F10+E10 -> -0.0017773895
A11: 1759.5 | B11: 0.012743487 | C11: 0.0045639544 | D11: 0.00067001997 | E11: -0.00010388792 | F11: -0.0026478089 | G11: 0.0021023221 | H11: 0 | I11: -0.001118388 | J11: 0.00036544875 | K11: 0.00031022066 | L11: 0.067512332 | M11: 0.23192873 | N11: -0.0027516968 | O11: 0.0052339816 | P11: 7.1622086e-09 | Q11: 0.016885376 | R11: 0.31632643 | S11: -0.00044271859 | Z11: =K11+J11+I11+H11+G11+D11+C11+B11+P11 -> 0.019637072 | AA11: =10^((Z11+$V$100)/$V$99) -> 279.18735 | AE11: =F11+E11 -> -0.0027516968
A12: 1760.5 | B12: 0.014157747 | C12: 0.0050695374 | D12: 0.00074442506 | E12: -0.0010371095 | F12: -0.0055869598 | G12: 0.002476618 | H12: 0 | I12: -0.0012627866 | J12: 0.00053443818 | K12: 0.00034468963 | L12: 0.092395267 | M12: 0.050240462 | N12: -0.0066240693 | O12: 0.0058139704 | P12: 7.9580096e-09 | Q12: 0.015440607 | R12: 0.15807634 | S12: -0.00038365877 | Z12: =K12+J12+I12+H12+G12+D12+C12+B12+P12 -> 0.022064676 | AA12: =10^((Z12+$V$100)/$V$99) -> 279.30984 | AE12: =F12+E12 -> -0.0066240693
A13: 1761.5 | B13: 0.01557167 | C13: 0.0055748176 | D13: 0.00081882185 | E13: -0.00019168416 | F13: -0.0051028097 | G13: 0.003160343 | H13: 0 | I13: -0.00141694 | J13: 0.00069548802 | K13: 0.00037915859 | L13: 0.086248636 | M13: -1.2562396 | N13: -0.0052944939 | O13: 0.0063936482 | P13: 8.7538106e-09 | Q13: 0.019488874 | R13: -1.1505021 | S13: -0.00034229335 | Z13: =K13+J13+I13+H13+G13+D13+C13+B13+P13 -> 0.024783368 | AA13: =10^((Z13+$V$100)/$V$99) -> 279.44708 | AE13: =F13+E13 -> -0.0052944939
... A76: 1824.5 | B76: 0.10397882 | C76: 0.036817142 | D76: 0.0054892929 | E76: 0.00083546444 | F76: -0.030518834 | G76: 0.017336345 | H76: 0 | I76: -0.02173655 | J76: 0.0049679994 | K76: 0.0025507032 | L76: -0.050178488 | M76: -0.063608989 | N76: -0.029683369 | O76: 0.042306494 | P76: 5.8889271e-08 | Q76: 0.11972045 | R76: 0.0059329694 | S76: -0.014217848 | Z76: =K76+J76+I76+H76+G76+D76+C76+B76+P76 -> 0.14940382 | AA76: =10^((Z76+$V$100)/$V$99) -> 285.81094 | AE76: =F76+E76 -> -0.029683369
A77: 1825.5 | B77: 0.1053716 | C77: 0.037303989 | D77: 0.0055631682 | E77: -0.00049755863 | F77: -0.035563842 | G77: 0.017558915 | H77: 0 | I77: -0.022306606 | J77: 0.0052001525 | K77: 0.0025851722 | L77: -0.020240964 | M77: 0.077164765 | N77: -0.0360614 | O77: 0.042867217 | P77: 5.9685072e-08 | Q77: 0.11521505 | R77: 0.17213885 | S77: -0.014521282 | Z77: =K77+J77+I77+H77+G77+D77+C77+B77+P77 -> 0.15127645 | AA77: =10^((Z77+$V$100)/$V$99) -> 285.90767 | AB77: 2.4562258 | AE77: =F77+E77 -> -0.0360614
A78: 1826.5 | B78: 0.10676404 | C78: 0.037790562 | D78: 0.0056370354 | E78: 0.00042506605 | F78: -0.033394632 | G78: 0.01758031 | H78: 0 | I78: -0.022877353 | J78: 0.0052350265 | K78: 0.0026196412 | L78: 0.01314429 | M78: 0.20123791 | N78: -0.032969566 | O78: 0.043427658 | P78: 6.0480873e-08 | Q78: 0.11977976 | R78: 0.33416196 | S78: -0.015022685 | Z78: =K78+J78+I78+H78+G78+D78+C78+B78+P78 -> 0.15274933 | AA78: =10^((Z78+$V$100)/$V$99) -> 285.98377 | AB78: 2.4563414 | AE78: =F78+E78 -> -0.032969566
A79: 1827.5 | B79: 0.10815616 | C79: 0.038276861 | D79: 0.0057108947 | E79: 0.00015300989 | F79: -0.037098198 | G79: 0.018360468 | H79: 0 | I79: -0.023448757 | J79: 0.005676224 | K79: 0.0026541101 | L79: 0.037543607 | M79: 0.16409647 | N79: -0.036945188 | O79: 0.043987817 | P79: 6.1276674e-08 | Q79: 0.11844084 | R79: 0.32008092 | S79: -0.015118423 | Z79: =K79+J79+I79+H79+G79+D79+C79+B79+P79 -> 0.15538603 | AA79: =10^((Z79+$V$100)/$V$99) -> 286.12005 | AB79: 2.4565483 | AE79: =F79+E79 -> -0.036945188
A80: 1828.5 | B80: 0.10954796 | C80: 0.038762887 | D80: 0.0057847459 | E80: -0.0012217627 | F80: -0.048377911 | G80: 0.020578005 | H80: 0 | I80: -0.024020767 | J80: 0.0068808149 | K80: 0.0026885791 | L80: 0.044953885 | M80: 0.20833486 | N80: -0.049599674 | O80: 0.044547695 | P80: 6.2072475e-08 | Q80: 0.11062261 | R80: 0.36391136 | S80: -0.014451373 | Z80: =K80+J80+I80+H80+G80+D80+C80+B80+P80 -> 0.16022229 | AA80: =10^((Z80+$V$100)/$V$99) -> 286.37019 | AB80: 2.4569278 | AE80: =F80+E80 -> -0.049599674
A81: 1829.5 | B81: 0.11093943 | C81: 0.03924864 | D81: 0.0058585892 | E81: -0.00086545923 | F81: -0.043741697 | G81: 0.019518595 | H81: 0 | I81: -0.024593401 | J81: 0.0063033077 | K81: 0.002723048 | L81: 0.035921146 | M81: 0.11233137 | N81: -0.044607156 | O81: 0.045107292 | P81: 6.2868276e-08 | Q81: 0.11539112 | R81: 0.26364363 | S81: -0.015567045 | Z81: =K81+J81+I81+H81+G81+D81+C81+B81+P81 -> 0.15999828 | AA81: =10^((Z81+$V$100)/$V$99) -> 286.35859 | AB81: 2.4569102 | AE81: =F81+E81 -> -0.044607156
A82: 1830.5 | B82: 0.11233058 | C82: 0.039734121 | D82: 0.0059324244 | E82: -0.0013478136 | F82: -0.04791236 | G82: 0.020120989 | H82: 0 | I82: -0.025271474 | J82: 0.0067132196 | K82: 0.002757517 | L82: 0.016186405 | M82: 0.19059517 | N82: -0.049260173 | O82: 0.045666609 | P82: 6.3664077e-08 | Q82: 0.11305727 | R82: 0.31983884 | S82: -0.015800737 | Z82: =K82+J82+I82+H82+G82+D82+C82+B82+P82 -> 0.16231744 | AA82: =10^((Z82+$V$100)/$V$99) -> 286.47862 | AB82: 2.4570922 | AE82: =F82+E82 -> -0.049260173
A83: 1831.5 | B83: 0.11372141 | C83: 0.04021933 | D83: 0.0060062517 | E83: -0.00011671495 | F83: -0.041086007 | G83: 0.019114738 | H83: 0 | I83: -0.026054931 | J83: 0.0061467082 | K83: 0.002791986 | L83: -0.010365793 | M83: -2.2322494 | N83: -0.041202722 | O83: 0.046225646 | P83: 6.4459878e-08 | Q83: 0.12074283 | R83: -2.1218724 | S83: -0.017116237 | Z83: =K83+J83+I83+H83+G83+D83+C83+B83+P83 -> 0.16194555 | AA83: =10^((Z83+$V$100)/$V$99) -> 286.45937 | AB83: 2.457063 | AE83: =F83+E83 -> -0.041202722
A84: 1832.5 | B84: 0.11511191 | C84: 0.040704267 | D84: 0.006080071 | E84: 0.00041594676 | F84: -0.03956812 | G84: 0.019144572 | H84: 0 | I84: -0.026838895 | J84: 0.0061186115 | K84: 0.0028264549 | L84: -0.035482736 | M84: -1.7917386 | N84: -0.039152173 | O84: 0.046784404 | P84: 6.5255679e-08 | Q84: 0.12399488 | R84: -1.7032265 | S84: -0.017893829 | Z84: =K84+J84+I84+H84+G84+D84+C84+B84+P84 -> 0.16314705 | AA84: =10^((Z84+$V$100)/$V$99) -> 286.52157 | AB84: 2.4571573 | AE84: =F84+E84 -> -0.039152173
A85: 1833.5 | B85: 0.11650208 | C85: 0.041188933 | D85: 0.0061538823 | E85: -5.85048e-05 | F85: -0.041673382 | G85: 0.019175019 | H85: 0 | I85: -0.027623369 | J85: 0.0062529522 | K85: 0.0028609239 | L85: -0.051052121 | M85: -0.75523992 | N85: -0.041731887 | O85: 0.047342882 | P85: 6.605148e-08 | Q85: 0.1227786 | R85: -0.68351344 | S85: -0.018509493 | Z85: =K85+J85+I85+H85+G85+D85+C85+B85+P85 -> 0.16451049 | AA85: =10^((Z85+$V$100)/$V$99) -> 286.59216 | AB85: 2.4572643 | AE85: =F85+E85 -> -0.041731887
A86: 1834.5 | B86: 0.11789194 | C86: 0.041673329 | D86: 0.0062276857 | E86: -0.0014796425 | F86: -0.051223508 | G86: 0.020746873 | H86: 0 | I86: -0.028408285 | J86: 0.0071807835 | K86: 0.0028953929 | L86: -0.048509225 | M86: -0.078318737 | N86: -0.05270315 | O86: 0.047901081 | P86: 6.6847281e-08 | Q86: 0.11550463 | R86: -0.011323332 | S86: -0.018332108 | Z86: =K86+J86+I86+H86+G86+D86+C86+B86+P86 -> 0.16820778 | AA86: =10^((Z86+$V$100)/$V$99) -> 286.78369 | AB86: 2.4575544 | AE86: =F86+E86 -> -0.05270315
A87: 1835.5 | B87: 0.11928146 | C87: 0.042157453 | D87: 0.0063014811 | E87: -0.00022256544 | F87: -0.047985007 | G87: 0.020679096 | H87: 0 | I87: -0.02919366 | J87: 0.0071451525 | K87: 0.0029298618 | L87: -0.015155173 | M87: -1.9846822 | N87: -0.048207572 | O87: 0.048459002 | P87: 6.7643082e-08 | Q87: 0.12109334 | R87: -1.878744 | S87: -0.019118645 | Z87: =K87+J87+I87+H87+G87+D87+C87+B87+P87 -> 0.16930092 | AA87: =10^((Z87+$V$100)/$V$99) -> 286.84034 | AB87: 2.4576402 | AE87: =F87+E87 -> -0.048207572
A88: 1836.5 | B88: 0.12067067 | C88: 0.042641308 | D88: 0.0063752685 | E88: -0.00086701032 | F88: -0.050202764 | G88: 0.020309387 | H88: 0 | I88: -0.029979426 | J88: 0.0071980805 | K88: 0.0029643308 | L88: 0.043861844 | M88: -1.9528897 | N88: -0.051069775 | O88: 0.049016645 | P88: 6.8438883e-08 | Q88: 0.11910991 | R88: -1.7899179 | S88: -0.019817015 | Z88: =K88+J88+I88+H88+G88+D88+C88+B88+P88 -> 0.17017969 | AA88: =10^((Z88+$V$100)/$V$99) -> 286.88589 | AB88: 2.4577092 | AE88: =F88+E88 -> -0.051069775
... A98: 1846.5 | B98: 0.13454498 | C98: 0.047465094 | D98: 0.0071127056 | E98: -0.00036267113 | F98: -0.062587087 | G98: 0.022738938 | H98: 0 | I98: -0.037514351 | J98: 0.0090937551 | K98: 0.0033090204 | L98: -0.041878976 | M98: -0.43453288 | N98: -0.062949758 | O98: 0.054577876 | P98: 7.6396892e-08 | Q98: 0.12380046 | R98: -0.35261139 | S98: -0.025111576 | Z98: =K98+J98+I98+H98+G98+D98+C98+B98+P98 -> 0.18675022 | AA98: =10^((Z98+$V$100)/$V$99) -> 287.74614 | AB98: 2.4590095 | AE98: =F98+E98 -> -0.062949758
A99: 1847.5 | B99: 0.13593064 | C99: 0.047946005 | D99: 0.0071864057 | E99: -0.0011089733 | F99: -0.070351873 | G99: 0.024031181 | H99: 0 | I99: -0.038250614 | J99: 0.009967246 | K99: 0.0033434894 | L99: -0.029538913 | M99: -0.0042754419 | N99: -0.071460846 | O99: 0.055132488 | P99: 7.7192693e-08 | Q99: 0.11869358 | R99: 0.08487923 | S99: -0.024939879 | V99: 12.743332 | Z99: =K99+J99+I99+H99+G99+D99+C99+B99+P99 -> 0.19015443 | AA99: =10^((Z99+$V$100)/$V$99) -> 287.92319 | AB99: 2.4592766 | AE99: =F99+E99 -> -0.071460846
A100: 1848.5 | B100: 0.13731598 | C100: 0.04842665 | D100: 0.0072600979 | E100: -0.0024366531 | F100: -0.079618404 | G100: 0.025785612 | H100: 0 | I100: -0.038986962 | J100: 0.010914293 | K100: 0.0033779583 | L100: -0.017167648 | M100: 0.19689949 | N100: -0.082055057 | O100: 0.055686826 | P100: 7.7988494e-08 | Q100: 0.11203865 | R100: 0.29177049 | S100: -0.024694711 | V100: 31.149224 | Z100: =K100+J100+I100+H100+G100+D100+C100+B100+P100 -> 0.19409371 | AA100: =10^((Z100+$V$100)/$V$99) -> 288.1282 | AB100: 2.4595858 | AE100: =F100+E100 -> -0.082055057
A101: 1849.5 | B101: 0.138701 | C101: 0.048907031 | D101: 0.0073337822 | E101: -0.0021648165 | F101: -0.077621974 | G101: 0.025180044 | H101: 0 | I101: -0.039723377 | J101: 0.010630965 | K101: 0.0034124273 | L101: -0.0047963835 | M101: 0.23735602 | N101: -0.07978679 | O101: 0.056240892 | P101: 7.8784295e-08 | Q101: 0.11465516 | R101: 0.34721479 | S101: -0.025679985 | Z101: =K101+J101+I101+H101+G101+D101+C101+B101+P101 -> 0.19444195 | AA101: =10^((Z101+$V$100)/$V$99) -> 288.14634 | AB101: 2.4596131 | AE101: =F101+E101 -> -0.07978679
A102: 1850.5 | B102: 0.14008569 | C102: 0.049387147 | D102: 0.0074074585 | E102: -0.0023160862 | F102: -0.080306524 | G102: 0.025615178 | H102: 0 | I102: -0.040767195 | J102: 0.011008615 | K102: 0.0034468963 | L102: 0.0075280794 | M102: 0.24414237 | N102: -0.08262261 | O102: 0.056794685 | P102: 7.9580096e-08 | Q102: 0.11356126 | R102: 0.36523171 | S102: -0.026311684 | Z102: =K102+J102+I102+H102+G102+D102+C102+B102+P102 -> 0.19618387 | AA102: =10^((Z102+$V$100)/$V$99) -> 288.23704 | AB102: 2.4597498 | AE102: =F102+E102 -> -0.08262261
A103: 1851.5 | B103: 0.14242946 | C103: 0.049490248 | D103: 0.0077054543 | E103: -0.00091928299 | F103: -0.073427571 | G103: 0.024454565 | H103: 0 | I103: -0.042118476 | J103: 0.010416004 | K103: 0.0034543253 | L103: 0.0020678743 | M103: 0.24503909 | N103: -0.074346854 | O103: 0.057195784 | P103: 8.2282773e-08 | Q103: 0.12148481 | R103: 0.36859177 | S103: -0.028248147 | Z103: =K103+J103+I103+H103+G103+D103+C103+B103+P103 -> 0.19583166 | AA103: =10^((Z103+$V$100)/$V$99) -> 288.2187 | AE103: =F103+E103 -> -0.074346854
A104: 1852.5 | B104: 0.14508002 | C104: 0.049951329 | D104: 0.0080033537 | E104: -0.00026402083 | F104: -0.070948095 | G104: 0.023995278 | H104: 0 | I104: -0.043469704 | J104: 0.010219134 | K104: 0.0034874698 | L104: 0.0012566438 | M104: 0.24501132 | N104: -0.071212116 | O104: 0.057954768 | P104: 8.5334116e-08 | Q104: 0.12605485 | R104: 0.37232281 | S104: -0.0297631 | Z104: =K104+J104+I104+H104+G104+D104+C104+B104+P104 -> 0.19726696 | AA104: =10^((Z104+$V$100)/$V$99) -> 288.29346 | AE104: =F104+E104 -> -0.071212116
A105: 1853.5 | B105: 0.14746032 | C105: 0.050712849 | D105: 0.008381922 | E105: -0.00069165276 | F105: -0.074799541 | G105: 0.024671005 | H105: 0 | I105: -0.044820886 | J105: 0.010628766 | K105: 0.0035422401 | L105: -0.0088681364 | M105: -0.001429855 | N105: -0.075491193 | O105: 0.059094859 | P105: 8.839851e-08 | Q105: 0.12508511 | R105: 0.11478711 | S105: -0.03064988 | Z105: =K105+J105+I105+H105+G105+D105+C105+B105+P105 -> 0.2005763 | AA105: =10^((Z105+$V$100)/$V$99) -> 288.4659 | AE105: =F105+E105 -> -0.075491193
A106: 1854.5 | B106: 0.14949455 | C106: 0.051526921 | D106: 0.0087714733 | E106: -0.0027176602 | F106: -0.088982038 | G106: 0.026801356 | H106: 0 | I106: -0.046171979 | J106: 0.011971739 | K106: 0.0036008424 | L106: -0.022721457 | M106: -0.28257773 | N106: -0.091699698 | O106: 0.060298486 | P106: 9.1471179e-08 | Q106: 0.1142953 | R106: -0.19100389 | S106: -0.030599397 | Z106: =K106+J106+I106+H106+G106+D106+C106+B106+P106 -> 0.20599499 | AA106: =10^((Z106+$V$100)/$V$99) -> 288.74847 | AE106: =F106+E106 -> -0.091699698
A107: 1855.5 | B107: 0.15114382 | C107: 0.052506068 | D107: 0.0091903876 | E107: -0.0013974305 | F107: -0.085175845 | G107: 0.026757796 | H107: 0 | I107: -0.047522967 | J107: 0.011812538 | K107: 0.0036713967 | L107: -0.031254977 | M107: 0.073721743 | N107: -0.086573276 | O107: 0.06169655 | P107: 9.4557112e-08 | Q107: 0.12098586 | R107: 0.16345262 | S107: -0.032039032 | Z107: =K107+J107+I107+H107+G107+D107+C107+B107+P107 -> 0.20755913 | AA107: =10^((Z107+$V$100)/$V$99) -> 288.83009 | AE107: =F107+E107 -> -0.086573276
A108: 1856.5 | B108: 0.15304209 | C108: 0.053401331 | D108: 0.0096126156 | E108: -0.0020844075 | F108: -0.086395581 | G108: 0.026150637 | H108: 0 | I108: -0.048873807 | J108: 0.011625778 | K108: 0.0037359804 | L108: -0.033641867 | M108: 0.15512135 | N108: -0.088479988 | O108: 0.063014045 | P108: 9.7657953e-08 | Q108: 0.12021473 | R108: 0.24169422 | S108: -0.033512048 | Z108: =K108+J108+I108+H108+G108+D108+C108+B108+P108 -> 0.20869472 | AA108: =10^((Z108+$V$100)/$V$99) -> 288.88936 | AE108: =F108+E108 -> -0.088479988
A109: 1857.5 | B109: 0.15584122 | C109: 0.054412554 | D109: 0.0099945862 | E109: -0.0021112454 | F109: -0.09320808 | G109: 0.028748672 | H109: 0 | I109: -0.050224479 | J109: 0.012718338 | K109: 0.0038090008 | L109: -0.027666842 | M109: -0.78204914 | N109: -0.095319325 | O109: 0.064407241 | P109: 1.0077535e-07 | Q109: 0.11998067 | R109: -0.68973531 | S109: -0.033697141 | Z109: =K109+J109+I109+H109+G109+D109+C109+B109+P109 -> 0.2153 | AA109: =10^((Z109+$V$100)/$V$99) -> 289.23436 | AE109: =F109+E109 -> -0.095319325
A110: 1858.5 | B110: 0.15883039 | C110: 0.055572837 | D110: 0.010317745 | E110: -0.0024741872 | F110: -0.097187043 | G110: 0.030128815 | H110: 0 | I110: -0.051574969 | J110: 0.013208751 | K110: 0.0038928784 | L110: -0.010802609 | M110: -0.39629725 | N110: -0.099661231 | O110: 0.065890686 | P110: 1.0391093e-07 | Q110: 0.12071532 | R110: -0.28638454 | S110: -0.03447334 | Z110: =K110+J110+I110+H110+G110+D110+C110+B110+P110 -> 0.22037655 | AA110: =10^((Z110+$V$100)/$V$99) -> 289.49979 | AE110: =F110+E110 -> -0.099661231
A111: 1859.5 | B111: 0.16202959 | C111: 0.056815068 | D111: 0.010853392 | E111: -0.0030944316 | F111: -0.099134155 | G111: 0.029795695 | H111: 0 | I111: -0.052925221 | J111: 0.013154798 | K111: 0.0039828233 | L111: 0.0034563264 | M111: 0.076207681 | N111: -0.10222859 | O111: 0.067668567 | P111: 1.0706636e-07 | Q111: 0.12147767 | R111: 0.20114167 | S111: -0.0357876 | Z111: =K111+J111+I111+H111+G111+D111+C111+B111+P111 -> 0.22370625 | AA111: =10^((Z111+$V$100)/$V$99) -> 289.67402 | AE111: =F111+E111 -> -0.10222859
...

Sheet Extension inputs
A1: Year | B1: HadCRUT5.1 anomaly (°C) | C1: Temperature SE (°C) | D1: IAP 0–6000 m (ZJ) | E1: IAP SE (ZJ) | F1: Annual TSI (W/m²) | G1: 525 nm AOD ×1000 | H1: Observed CO2 (ppm) | I1: eCO2 / CO2
A2: 1850 | B2: -0.42648312 | C2: 0.086558442 | F2: 1361.7836
A3: 1851 | B3: -0.2635183 | C3: 0.087122259 | F3: 1361.7212
A4: 1852 | B4: -0.22405294 | C4: 0.082300038 | F4: 1361.6761
A5: 1853 | B5: -0.26234877 | C5: 0.079540539 | F5: 1361.5374
A6: 1854 | B6: -0.29358405 | C6: 0.068980705 | F6: 1361.363
A7: 1855 | B7: -0.29138646 | C7: 0.067710675 | F7: 1361.1906
A8: 1856 | B8: -0.32809034 | C8: 0.072110575 | F8: 1361.155
A9: 1857 | B9: -0.46585593 | C9: 0.075915982 | F9: 1361.314
A10: 1858 | B10: -0.3967561 | C10: 0.075354932 | F10: 1361.6183
A11: 1859 | B11: -0.29197732 | C11: 0.071113728 | F11: 1361.8894
A12: 1860 | B12: -0.40712935 | C12: 0.075532525 | F12: 1361.9712
A13: 1861 | B13: -0.4636966 | C13: 0.08527384 | F13: 1361.8658
... A130: 1978 | B130: 0.005504774 | C130: 0.019832049 | F130: 1361.8116
A131: 1979 | B131: 0.0881039 | C131: 0.014426632 | F131: 1362.1752 | G131: 5.473
A132: 1980 | B132: 0.1915224 | C132: 0.016284183 | F132: 1362.2012 | G132: 7.638
A133: 1981 | B133: 0.24696657 | C133: 0.015620055 | F133: 1362.2485 | G133: 9.386
A134: 1982 | B134: 0.030967088 | C134: 0.020248185 | F134: 1361.8069 | G134: 28.96
A135: 1983 | B135: 0.22084606 | C135: 0.017762305 | F135: 1361.8102 | G135: 48.222
A136: 1984 | B136: 0.04603783 | C136: 0.016992838 | F136: 1361.4021 | G136: 28.374
A137: 1985 | B137: 0.045988217 | C137: 0.016537193 | F137: 1361.2557 | G137: 14.164
A138: 1986 | B138: 0.09232101 | C138: 0.016175331 | F138: 1361.2617 | G138: 15.939
A139: 1987 | B139: 0.23820166 | C139: 0.01536689 | F139: 1361.3965 | G139: 10.816
A140: 1988 | B140: 0.27761188 | C140: 0.017482005 | F140: 1361.7025 | G140: 7.926
A141: 1989 | B141: 0.17489623 | C141: 0.017683965 | F141: 1362.2012 | G141: 6.002
A142: 1990 | B142: 0.35504323 | C142: 0.017601675 | F142: 1362.12 | G142: 6.356
A143: 1991 | B143: 0.3338096 | C143: 0.017801807 | F143: 1362.0125 | G143: 50.011
A144: 1992 | B144: 0.12002608 | C144: 0.0167813 | D144: -200.625 | E144: 16.95485 | F144: 1361.8813 | G144: 112.427
A145: 1993 | B145: 0.16109136 | C145: 0.019168385 | D145: -205.975 | E145: 14.968991 | F145: 1361.6144 | G145: 56.226
A146: 1994 | B146: 0.22744027 | C146: 0.01819119 | D146: -180.94167 | E146: 14.161112 | F146: 1361.3958 | G146: 17.943
A147: 1995 | B147: 0.37113267 | C147: 0.016589598 | D147: -178.85833 | E147: 13.839845 | F147: 1361.3113 | G147: 8.73
A148: 1996 | B148: 0.2708395 | C148: 0.016127013 | D148: -155.025 | E148: 14.456964 | F148: 1361.2351 | G148: 5.583
A149: 1997 | B149: 0.41507134 | C149: 0.016238032 | D149: -165.025 | E149: 14.642048 | F149: 1361.3572 | G149: 4.53
A150: 1998 | B150: 0.571961 | C150: 0.016523115 | D150: -147.53333 | E150: 13.82846 | F150: 1361.7025 | G150: 4.423
A151: 1999 | B151: 0.3180378 | C151: 0.016307562 | D151: -126.54167 | E151: 14.391235 | F151: 1361.9731 | G151: 4.25
A152: 2000 | B152: 0.32550883 | C152: 0.016370008 | D152: -127.53333 | E152: 13.958593 | F152: 1362.2537 | G152: 4.24 | H152: 369.71 | I152: =toyKFmodelData8c!C151/H152 -> 1.2882727
A153: 2001 | B153: 0.48345044 | C153: 0.016896537 | D153: -122.80833 | E153: 13.136065 | F153: 1362.0814 | G153: 4.399 | H153: 371.32 | I153: =toyKFmodelData8c!C152/H153 -> 1.2903537
A154: 2002 | B154: 0.5371589 | C154: 0.01511195 | D154: -91.175 | E154: 12.047582 | F154: 1362.1906 | G154: 4.177 | H154: 373.45 | I154: =toyKFmodelData8c!C153/H154 -> 1.2954175
A155: 2003 | B155: 0.5382795 | C155: 0.016733573 | D155: -59.825 | E155: 10.555894 | F155: 1361.6907 | G155: 4.958 | H155: 375.98 | I155: =toyKFmodelData8c!C154/H155 -> 1.2984064
A156: 2004 | B156: 0.46242514 | C156: 0.01518427 | D156: -62.816667 | E156: 8.1851619 | F156: 1361.4706 | G156: 4.435 | H156: 377.7 | I156: =toyKFmodelData8c!C155/H156 -> 1.3031641
...
